ts_recv,ts_event,rtype,publisher_id,instrument_id,action,side,price,size,channel_id,order_id,flags,ts_in_delta,sequence,symbol
1654864201100858345,1654864201100846675,160,2,7370,T,A,265760000000,14,0,0,130,11670,11404021,MSFT
1654864201100858345,1654864201100846675,160,2,7370,F,B,265760000000,14,0,12448607,130,11670,11404021,MSFT
1654864201100858345,1654864201100846675,160,2,7370,C,B,265760000000,14,0,12448607,130,11670,11404021,MSFT
1654864201100878961,1654864201100868549,160,2,7370,A,A,265950000000,100,0,12509331,130,10412,11404022,MSFT
1654864201100899733,1654864201100886880,160,2,7370,T,A,265700000000,2,0,0,128,12853,11404028,MSFT
1654864201100899733,1654864201100886880,160,2,7370,F,B,265700000000,2,0,11713363,128,12853,11404028,MSFT
1654864201100899733,1654864201100886880,160,2,7370,C,B,265700000000,2,0,11713363,128,12853,11404028,MSFT
1654864201100918188,1654864201100907886,160,2,7370,A,A,265900000000,100,0,12509383,130,10302,11404030,MSFT
1654864201101184457,1654864201101173171,160,2,7370,A,A,265990000000,100,0,12509475,130,11286,11404044,MSFT
1654864201101903885,1654864201101893644,160,2,7370,C,A,265950000000,100,0,12509331,130,10241,11404066,MSFT
1654864201102090016,1654864201102078647,160,2,7370,C,A,265900000000,100,0,12509383,130,11369,11404082,MSFT
1654864201104775927,1654864201104765074,160,2,7370,A,A,265850000000,100,0,12509707,130,10853,11404199,MSFT
1654864201124873206,1654864201124863293,160,2,7370,C,A,265990000000,100,0,12509475,130,9913,11404961,MSFT
1654864201126685671,1654864201126674989,160,2,7370,C,A,265850000000,100,0,12509707,130,10682,11404998,MSFT
1654864203914065971,1654864203914054466,160,2,7370,A,A,265970000000,100,0,12545979,130,11505,11423654,MSFT
1654864203915069654,1654864203915055569,160,2,7370,T,A,265580000000,1,0,0,0,14085,11423666,MSFT
1654864203915069654,1654864203915055569,160,2,7370,F,B,265580000000,1,0,11166351,0,14085,11423666,MSFT
1654864203915069654,1654864203915055569,160,2,7370,C,B,265580000000,1,0,11166351,0,14085,11423666,MSFT
1654864203915069654,1654864203915055569,160,2,7370,T,A,265580000000,1,0,0,130,14085,11423667,MSFT
1654864203915069654,1654864203915055569,160,2,7370,F,B,265580000000,1,0,11183519,130,14085,11423667,MSFT
1654864203915069654,1654864203915055569,160,2,7370,C,B,265580000000,1,0,11183519,130,14085,11423667,MSFT
1654864203915483884,1654864203915473679,160,2,7370,C,A,265970000000,100,0,12545979,130,10205,11423668,MSFT
1654864204088582798,1654864204088570588,160,2,7370,T,A,265500000000,1,0,0,130,12210,11425337,MSFT
1654864204088582798,1654864204088570588,160,2,7370,F,B,265500000000,1,0,12190967,130,12210,11425337,MSFT
1654864204088582798,1654864204088570588,160,2,7370,C,B,265500000000,1,0,12190967,130,12210,11425337,MSFT
1654864204315070293,1654864204315059704,160,2,7370,A,B,247000000000,200,0,12551491,130,10589,11426117,MSFT
1654864205178959839,1654864205178947937,160,2,7370,T,N,265450000000,51,0,0,130,11902,11429992,MSFT
1654864205178985945,1654864205178974283,160,2,7370,T,N,265450000000,63,0,0,130,11662,11429994,MSFT
1654864205179485745,1654864205179475201,160,2,7370,A,A,265950000000,100,0,12559899,130,10544,11429996,MSFT
1654864205180906176,1654864205180895978,160,2,7370,C,A,265950000000,100,0,12559899,130,10198,11430009,MSFT
1654864206192037358,1654864206192026648,160,2,7370,A,B,212320000000,100,0,12570859,130,10710,11437353,MSFT
1654864206192061908,1654864206192051455,160,2,7370,A,A,319890000000,100,0,12570863,130,10453,11437354,MSFT
1654864206492437973,1654864206492426164,160,2,7370,T,A,265400000000,100,0,0,130,11809,11439355,MSFT
1654864206492437973,1654864206492426164,160,2,7370,F,B,265400000000,100,0,12467219,130,11809,11439355,MSFT
1654864206492437973,1654864206492426164,160,2,7370,C,B,265400000000,100,0,12467219,130,11809,11439355,MSFT
1654864206492460280,1654864206492448589,160,2,7370,A,A,265880000000,100,0,12576163,0,11691,11439356,MSFT
1654864206492460280,1654864206492449635,160,2,7370,A,A,265880000000,100,0,12576167,130,10645,11439357,MSFT
1654864206492461875,1654864206492451355,160,2,7370,A,A,265880000000,100,0,12576171,130,10520,11439358,MSFT
1654864206492474406,1654864206492463531,160,2,7370,A,A,265880000000,100,0,12576203,130,10875,11439359,MSFT
1654864206492478214,1654864206492467508,160,2,7370,A,A,265880000000,100,0,12576207,130,10706,11439360,MSFT
1654864206492964893,1654864206492950036,160,2,7370,T,A,265350000000,2,0,0,130,14857,11439361,MSFT
1654864206492964893,1654864206492950036,160,2,7370,F,B,265350000000,2,0,11262123,130,14857,11439361,MSFT
1654864206492964893,1654864206492950036,160,2,7370,C,B,265350000000,2,0,11262123,130,14857,11439361,MSFT
1654864206492965966,1654864206492954665,160,2,7370,A,A,265930000000,100,0,12576287,130,11301,11439362,MSFT
1654864206492983274,1654864206492971968,160,2,7370,A,A,265770000000,100,0,12576291,130,11306,11439363,MSFT
1654864206492992058,1654864206492980039,160,2,7370,T,A,265280000000,4,0,0,130,12019,11439364,MSFT
1654864206492992058,1654864206492980039,160,2,7370,F,B,265280000000,4,0,9524687,130,12019,11439364,MSFT
1654864206492992058,1654864206492980039,160,2,7370,C,B,265280000000,4,0,9524687,130,12019,11439364,MSFT
1654864206493011683,1654864206493001017,160,2,7370,A,A,265670000000,100,0,12576319,130,10666,11439365,MSFT
1654864206493878282,1654864206493868177,160,2,7370,C,A,265880000000,100,0,12576167,130,10105,11439367,MSFT
1654864206494064487,1654864206494054373,160,2,7370,C,A,265880000000,100,0,12576203,130,10114,11439370,MSFT
1654864206494516484,1654864206494505987,160,2,7370,C,A,265930000000,100,0,12576287,130,10497,11439373,MSFT
1654864206494976349,1654864206494966255,160,2,7370,C,A,265880000000,100,0,12576163,130,10094,11439376,MSFT
1654864206495075248,1654864206495064344,160,2,7370,C,A,265770000000,100,0,12576291,130,10904,11439377,MSFT
1654864206495133757,1654864206495123623,160,2,7370,C,A,265670000000,100,0,12576319,130,10134,11439378,MSFT
1654864206502978190,1654864206502968050,160,2,7370,C,A,265880000000,100,0,12576207,130,10140,11439491,MSFT
1654864206512473478,1654864206512463165,160,2,7370,C,A,265880000000,100,0,12576171,130,10313,11439589,MSFT
1654864206570758387,1654864206570731026,160,2,7370,T,N,265040000000,10,0,0,0,27361,11439922,MSFT
1654864206570758387,1654864206570731026,160,2,7370,T,A,265000000000,1,0,0,0,27361,11439923,MSFT
1654864206570758387,1654864206570731026,160,2,7370,F,B,265000000000,1,0,9388371,0,27361,11439923,MSFT
1654864206570758387,1654864206570731026,160,2,7370,C,B,265000000000,1,0,9388371,0,27361,11439923,MSFT
1654864206570758387,1654864206570731026,160,2,7370,T,A,265000000000,15,0,0,0,27361,11439924,MSFT
1654864206570758387,1654864206570731026,160,2,7370,F,B,265000000000,15,0,12141191,0,27361,11439924,MSFT
1654864206570758387,1654864206570731026,160,2,7370,C,B,265000000000,15,0,12141191,0,27361,11439924,MSFT
1654864206570758387,1654864206570731026,160,2,7370,T,A,265000000000,1,0,0,0,27361,11439925,MSFT
1654864206570758387,1654864206570731026,160,2,7370,F,B,265000000000,1,0,12166483,0,27361,11439925,MSFT
1654864206570758387,1654864206570731026,160,2,7370,C,B,265000000000,1,0,12166483,0,27361,11439925,MSFT
1654864206570758387,1654864206570731026,160,2,7370,T,N,264970000000,10,0,0,0,27361,11439926,MSFT
1654864206570758387,1654864206570731026,160,2,7370,T,N,264880000000,10,0,0,0,27361,11439927,MSFT
1654864206570758387,1654864206570731026,160,2,7370,T,A,264870000000,10,0,0,0,27361,11439928,MSFT
1654864206570758387,1654864206570731026,160,2,7370,F,B,264870000000,10,0,8449499,0,27361,11439928,MSFT
1654864206570758387,1654864206570731026,160,2,7370,C,B,264870000000,10,0,8449499,0,27361,11439928,MSFT
1654864206570758387,1654864206570731026,160,2,7370,T,A,264790000000,1,0,0,0,27361,11439929,MSFT
1654864206570758387,1654864206570731026,160,2,7370,F,B,264790000000,1,0,10650899,0,27361,11439929,MSFT
1654864206570758387,1654864206570731026,160,2,7370,C,B,264790000000,1,0,10650899,0,27361,11439929,MSFT
1654864206570758387,1654864206570731026,160,2,7370,T,A,264790000000,1,0,0,0,27361,11439930,MSFT
1654864206570758387,1654864206570731026,160,2,7370,F,B,264790000000,1,0,10709563,0,27361,11439930,MSFT
1654864206570758387,1654864206570731026,160,2,7370,C,B,264790000000,1,0,10709563,0,27361,11439930,MSFT
1654864206570758387,1654864206570731026,160,2,7370,T,A,264710000000,1,0,0,0,27361,11439931,MSFT
1654864206570758387,1654864206570731026,160,2,7370,F,B,264710000000,1,0,980243,0,27361,11439931,MSFT
1654864206570758387,1654864206570731026,160,2,7370,C,B,264710000000,1,0,980243,0,27361,11439931,MSFT
1654864206570758387,1654864206570731026,160,2,7370,T,A,264710000000,1,0,0,0,27361,11439932,MSFT
1654864206570758387,1654864206570731026,160,2,7370,F,B,264710000000,1,0,5834375,0,27361,11439932,MSFT
1654864206570758387,1654864206570731026,160,2,7370,C,B,264710000000,1,0,5834375,0,27361,11439932,MSFT
1654864206570758387,1654864206570731026,160,2,7370,T,A,264700000000,1,0,0,0,27361,11439933,MSFT
1654864206570758387,1654864206570731026,160,2,7370,F,B,264700000000,1,0,7642967,0,27361,11439933,MSFT
1654864206570758387,1654864206570731026,160,2,7370,C,B,264700000000,1,0,7642967,0,27361,11439933,MSFT
1654864206570758387,1654864206570731026,160,2,7370,T,A,264700000000,1,0,0,130,27361,11439934,MSFT
1654864206570758387,1654864206570731026,160,2,7370,F,B,264700000000,1,0,12032635,130,27361,11439934,MSFT
1654864206570758387,1654864206570731026,160,2,7370,C,B,264700000000,1,0,12032635,130,27361,11439934,MSFT
1654864206570770442,1654864206570760151,160,2,7370,A,A,265770000000,100,0,12577843,130,10291,11439935,MSFT
1654864206570779144,1654864206570766245,160,2,7370,A,A,265770000000,100,0,12577863,130,12899,11439936,MSFT
1654864206570791132,1654864206570779398,160,2,7370,A,A,265770000000,100,0,12577887,130,11734,11439937,MSFT
1654864206571793958,1654864206571783863,160,2,7370,C,A,265770000000,100,0,12577843,130,10095,11439940,MSFT
1654864206571903362,1654864206571893096,160,2,7370,A,A,265890000000,100,0,12578007,130,10266,11439941,MSFT
1654864206573308080,1654864206573297982,160,2,7370,C,A,265890000000,100,0,12578007,130,10098,11439950,MSFT
1654864206581242315,1654864206581232339,160,2,7370,C,A,265770000000,100,0,12577887,130,9976,11439990,MSFT
1654864206590788215,1654864206590777639,160,2,7370,C,A,265770000000,100,0,12577863,130,10576,11440044,MSFT
1654864206725331924,1654864206725321510,160,2,7370,A,A,265850000000,100,0,12579975,130,10414,11440531,MSFT
1654864206726635314,1654864206726625300,160,2,7370,C,A,265850000000,100,0,12579975,130,10014,11440538,MSFT
1654864206885142296,1654864206885131564,160,2,7370,A,A,265360000000,100,0,12582279,130,10732,11441094,MSFT
1654864206886577233,1654864206886567133,160,2,7370,C,A,265360000000,100,0,12582279,130,10100,11441106,MSFT
1654864206970339350,1654864206970328866,160,2,7370,A,A,264970000000,10,0,12583747,130,10484,11441749,MSFT
1654864207034119784,1654864207034108214,160,2,7370,T,B,264970000000,5,0,0,130,11570,11442657,MSFT
1654864207034119784,1654864207034108214,160,2,7370,F,A,264970000000,5,0,12583747,130,11570,11442657,MSFT
1654864207034119784,1654864207034108214,160,2,7370,C,A,264970000000,5,0,12583747,130,11570,11442657,MSFT
1654864207055159427,1654864207055147689,160,2,7370,T,B,264970000000,5,0,0,130,11738,11442993,MSFT
1654864207055159427,1654864207055147689,160,2,7370,F,A,264970000000,5,0,12583747,130,11738,11442993,MSFT
1654864207055159427,1654864207055147689,160,2,7370,C,A,264970000000,5,0,12583747,130,11738,11442993,MSFT
1654864207055183425,1654864207055170186,160,2,7370,A,B,264600000000,100,0,12585731,130,13239,11442994,MSFT
1654864207056202828,1654864207056192597,160,2,7370,C,B,264600000000,100,0,12585731,130,10231,11443003,MSFT
1654864207296076826,1654864207296064968,160,2,7370,T,N,265100000000,6,0,0,130,11858,11445273,MSFT
1654864207563276723,1654864207563265749,160,2,7370,A,A,319200000000,100,0,12597291,130,10974,11448026,MSFT
1654864207786393128,1654864207786381348,160,2,7370,T,N,265100000000,10,0,0,130,11780,11450839,MSFT
1654864207814448475,1654864207814436821,160,2,7370,T,N,265100000000,34,0,0,130,11654,11451047,MSFT
1654864207814451195,1654864207814438430,160,2,7370,T,N,265100000000,7,0,0,130,12765,11451048,MSFT
1654864207844174496,1654864207844163669,160,2,7370,A,A,265810000000,100,0,12602783,130,10827,11451214,MSFT
1654864207845703013,1654864207845692862,160,2,7370,C,A,265810000000,100,0,12602783,130,10151,11451226,MSFT
1654864208596708171,1654864208596697513,160,2,7370,A,B,211800000000,100,0,12613355,130,10658,11456811,MSFT
1654864209193443670,1654864209193432372,160,2,7370,T,N,264750000000,6,0,0,130,11298,11464232,MSFT
1654864209546836040,1654864209546824524,160,2,7370,A,A,264720000000,100,0,12626047,130,11516,11466026,MSFT
1654864209548208557,1654864209548198544,160,2,7370,C,A,264720000000,100,0,12626047,130,10013,11466033,MSFT
1654864209550272025,1654864209550261127,160,2,7370,A,A,264720000000,100,0,12626199,130,10898,11466044,MSFT
1654864209551714092,1654864209551704052,160,2,7370,C,A,264720000000,100,0,12626199,130,10040,11466054,MSFT
1654864209592277362,1654864209592266714,160,2,7370,A,A,264700000000,6,0,12626659,130,10648,11466162,MSFT
1654864210038940258,1654864210038929186,160,2,7370,C,B,264500000000,10,0,11697523,130,11072,11468911,MSFT
1654864210044622637,1654864210044612321,160,2,7370,A,A,264710000000,100,0,12630119,130,10316,11468937,MSFT
1654864210046001203,1654864210045990101,160,2,7370,C,A,264710000000,100,0,12630119,130,11102,11468946,MSFT
1654864210047376848,1654864210047360133,160,2,7370,T,A,264500000000,1,0,0,0,16715,11468953,MSFT
1654864210047376848,1654864210047360133,160,2,7370,F,B,264500000000,1,0,499063,0,16715,11468953,MSFT
1654864210047376848,1654864210047360133,160,2,7370,C,B,264500000000,1,0,499063,0,16715,11468953,MSFT
1654864210047376848,1654864210047360133,160,2,7370,T,A,264500000000,1,0,0,0,16715,11468954,MSFT
1654864210047376848,1654864210047360133,160,2,7370,F,B,264500000000,1,0,2331779,0,16715,11468954,MSFT
1654864210047376848,1654864210047360133,160,2,7370,C,B,264500000000,1,0,2331779,0,16715,11468954,MSFT
1654864210047376848,1654864210047360133,160,2,7370,T,A,264500000000,1,0,0,0,16715,11468955,MSFT
1654864210047376848,1654864210047360133,160,2,7370,F,B,264500000000,1,0,7108339,0,16715,11468955,MSFT
1654864210047376848,1654864210047360133,160,2,7370,C,B,264500000000,1,0,7108339,0,16715,11468955,MSFT
1654864210047376848,1654864210047360133,160,2,7370,T,A,264500000000,1,0,0,130,16715,11468956,MSFT
1654864210047376848,1654864210047360133,160,2,7370,F,B,264500000000,1,0,8781935,130,16715,11468956,MSFT
1654864210047376848,1654864210047360133,160,2,7370,C,B,264500000000,1,0,8781935,130,16715,11468956,MSFT
1654864210440157383,1654864210440146037,160,2,7370,T,N,264510000000,4,0,0,130,11346,11471897,MSFT
1654864210445491552,1654864210445479590,160,2,7370,T,N,264510000000,5,0,0,130,11962,11471955,MSFT
1654864210478255227,1654864210478243400,160,2,7370,T,N,264510000000,5,0,0,130,11827,11472045,MSFT
1654864210499471239,1654864210499459584,160,2,7370,T,N,264510000000,4,0,0,130,11655,11472103,MSFT
1654864210547978244,1654864210547966525,160,2,7370,T,N,264510000000,5,0,0,130,11719,11472242,MSFT
1654864210557232350,1654864210557221023,160,2,7370,T,N,264510000000,5,0,0,130,11327,11472271,MSFT
1654864210598977029,1654864210598966020,160,2,7370,T,N,264510000000,4,0,0,130,11009,11472523,MSFT
1654864210613853454,1654864210613496974,160,2,7370,T,N,264510000000,2,0,0,0,356480,11472578,MSFT
1654864210613853454,1654864210613496974,160,2,7370,T,N,264540000000,3,0,0,130,356480,11472579,MSFT
1654864210649431839,1654864210649419453,160,2,7370,T,N,264540000000,5,0,0,130,12386,11472836,MSFT
1654864210660094492,1654864210660082910,160,2,7370,T,N,264540000000,5,0,0,130,11582,11472896,MSFT
1654864211080349296,1654864211080337763,160,2,7370,T,N,264510000000,3,0,0,130,11533,11476839,MSFT
1654864211167973421,1654864211167962212,160,2,7370,A,A,265750000000,150,0,12641863,130,11209,11477046,MSFT
1654864211882075645,1654864211882064728,160,2,7370,A,A,264680000000,100,0,12645159,130,10917,11480092,MSFT
1654864211882098361,1654864211882087637,160,2,7370,A,A,264670000000,100,0,12645167,130,10724,11480093,MSFT
1654864211882121548,1654864211882109307,160,2,7370,A,A,264640000000,100,0,12645179,130,12241,11480094,MSFT
1654864211882157929,1654864211882143764,160,2,7370,T,A,264400000000,1,0,0,0,14165,11480095,MSFT
1654864211882157929,1654864211882143764,160,2,7370,F,B,264400000000,1,0,9449139,0,14165,11480095,MSFT
1654864211882157929,1654864211882143764,160,2,7370,C,B,264400000000,1,0,9449139,0,14165,11480095,MSFT
1654864211882157929,1654864211882143764,160,2,7370,T,A,264280000000,1,0,0,130,14165,11480096,MSFT
1654864211882157929,1654864211882143764,160,2,7370,F,B,264280000000,1,0,12268503,130,14165,11480096,MSFT
1654864211882157929,1654864211882143764,160,2,7370,C,B,264280000000,1,0,12268503,130,14165,11480096,MSFT
1654864211883501313,1654864211883491013,160,2,7370,C,A,264680000000,100,0,12645159,130,10300,11480102,MSFT
1654864211883795931,1654864211883785371,160,2,7370,C,A,264670000000,100,0,12645167,130,10560,11480103,MSFT
1654864211884134002,1654864211884123855,160,2,7370,C,A,264640000000,100,0,12645179,130,10147,11480104,MSFT
1654864212817720085,1654864212817708229,160,2,7370,T,N,264430000000,12,0,0,130,11856,11485956,MSFT
1654864213055516466,1654864213055504931,160,2,7370,A,A,276140000000,100,0,12654015,130,11535,11487315,MSFT
1654864213055558547,1654864213055547410,160,2,7370,C,A,277690000000,100,0,509735,130,11137,11487317,MSFT
1654864213421092577,1654864213421079092,160,2,7370,T,A,264190000000,27,0,0,130,13485,11489323,MSFT
1654864213421092577,1654864213421079092,160,2,7370,F,B,264190000000,27,0,169423,130,13485,11489323,MSFT
1654864213421092577,1654864213421079092,160,2,7370,C,B,264190000000,27,0,169423,130,13485,11489323,MSFT
1654864213421113245,1654864213421102566,160,2,7370,A,A,264590000000,100,0,12656271,130,10679,11489324,MSFT
1654864213421836420,1654864213421822598,160,2,7370,T,A,264150000000,1,0,0,130,13822,11489327,MSFT
1654864213421836420,1654864213421822598,160,2,7370,F,B,264150000000,1,0,8798723,130,13822,11489327,MSFT
1654864213421836420,1654864213421822598,160,2,7370,C,B,264150000000,1,0,8798723,130,13822,11489327,MSFT
1654864213441129714,1654864213441119479,160,2,7370,C,A,264590000000,100,0,12656271,130,10235,11489431,MSFT
1654864213637763448,1654864213637750311,160,2,7370,A,A,299970000000,27,0,12656891,128,13137,11490386,MSFT
1654864215041140362,1654864215041123786,160,2,7370,T,N,264020000000,3,0,0,0,16576,11497652,MSFT
1654864215041140362,1654864215041123786,160,2,7370,T,A,264000000000,80,0,0,0,16576,11497653,MSFT
1654864215041140362,1654864215041123786,160,2,7370,F,B,264000000000,80,0,156511,0,16576,11497653,MSFT
1654864215041140362,1654864215041123786,160,2,7370,C,B,264000000000,80,0,156511,0,16576,11497653,MSFT
1654864215041140362,1654864215041123786,160,2,7370,T,A,264000000000,5,0,0,0,16576,11497654,MSFT
1654864215041140362,1654864215041123786,160,2,7370,F,B,264000000000,5,0,214243,0,16576,11497654,MSFT
1654864215041140362,1654864215041123786,160,2,7370,C,B,264000000000,5,0,214243,0,16576,11497654,MSFT
1654864215041140362,1654864215041123786,160,2,7370,T,A,264000000000,1,0,0,130,16576,11497655,MSFT
1654864215041140362,1654864215041123786,160,2,7370,F,B,264000000000,1,0,419831,130,16576,11497655,MSFT
1654864215041140362,1654864215041123786,160,2,7370,C,B,264000000000,1,0,419831,130,16576,11497655,MSFT
1654864215041147455,1654864215041123786,160,2,7370,T,A,264000000000,3,0,0,0,23669,11497656,MSFT
1654864215041147455,1654864215041123786,160,2,7370,F,B,264000000000,3,0,1833347,0,23669,11497656,MSFT
1654864215041147455,1654864215041123786,160,2,7370,C,B,264000000000,3,0,1833347,0,23669,11497656,MSFT
1654864215041147455,1654864215041123786,160,2,7370,T,A,264000000000,1,0,0,0,23669,11497657,MSFT
1654864215041147455,1654864215041123786,160,2,7370,F,B,264000000000,1,0,2509395,0,23669,11497657,MSFT
1654864215041147455,1654864215041123786,160,2,7370,C,B,264000000000,1,0,2509395,0,23669,11497657,MSFT
1654864215041147455,1654864215041123786,160,2,7370,T,A,264000000000,1,0,0,0,23669,11497658,MSFT
1654864215041147455,1654864215041123786,160,2,7370,F,B,264000000000,1,0,2591499,0,23669,11497658,MSFT
1654864215041147455,1654864215041123786,160,2,7370,C,B,264000000000,1,0,2591499,0,23669,11497658,MSFT
1654864215041147455,1654864215041123786,160,2,7370,T,A,264000000000,1,0,0,0,23669,11497659,MSFT
1654864215041147455,1654864215041123786,160,2,7370,F,B,264000000000,1,0,4652895,0,23669,11497659,MSFT
1654864215041147455,1654864215041123786,160,2,7370,C,B,264000000000,1,0,4652895,0,23669,11497659,MSFT
1654864215041147455,1654864215041123786,160,2,7370,T,A,264000000000,1,0,0,0,23669,11497660,MSFT
1654864215041147455,1654864215041123786,160,2,7370,F,B,264000000000,1,0,7091803,0,23669,11497660,MSFT
1654864215041147455,1654864215041123786,160,2,7370,C,B,264000000000,1,0,7091803,0,23669,11497660,MSFT
1654864215041147455,1654864215041123786,160,2,7370,T,A,264000000000,1,0,0,0,23669,11497661,MSFT
1654864215041147455,1654864215041123786,160,2,7370,F,B,264000000000,1,0,7895627,0,23669,11497661,MSFT
1654864215041147455,1654864215041123786,160,2,7370,C,B,264000000000,1,0,7895627,0,23669,11497661,MSFT
1654864215041147455,1654864215041123786,160,2,7370,T,A,264000000000,98,0,0,130,23669,11497662,MSFT
1654864215041147455,1654864215041123786,160,2,7370,F,B,264000000000,98,0,8033543,130,23669,11497662,MSFT
1654864215041147455,1654864215041123786,160,2,7370,C,B,264000000000,98,0,8033543,130,23669,11497662,MSFT
1654864215041258133,1654864215041247539,160,2,7370,A,A,264200000000,100,0,12666619,130,10594,11497667,MSFT
1654864215041305370,1654864215041290423,160,2,7370,T,A,264000000000,2,0,0,0,14947,11497669,MSFT
1654864215041305370,1654864215041290423,160,2,7370,F,B,264000000000,2,0,8033543,0,14947,11497669,MSFT
1654864215041305370,1654864215041290423,160,2,7370,C,B,264000000000,2,0,8033543,0,14947,11497669,MSFT
1654864215041305370,1654864215041290423,160,2,7370,T,A,264000000000,1,0,0,130,14947,11497670,MSFT
1654864215041305370,1654864215041290423,160,2,7370,F,B,264000000000,1,0,12353671,130,14947,11497670,MSFT
1654864215041305370,1654864215041290423,160,2,7370,C,B,264000000000,1,0,12353671,130,14947,11497670,MSFT
1654864215042730726,1654864215042720275,160,2,7370,C,A,264200000000,100,0,12666619,130,10451,11497675,MSFT
1654864215989842206,1654864215989828880,160,2,7370,T,A,263880000000,100,0,0,0,13326,11504020,MSFT
1654864215989842206,1654864215989828880,160,2,7370,F,B,263880000000,100,0,7920815,0,13326,11504020,MSFT
1654864215989842206,1654864215989828880,160,2,7370,C,B,263880000000,100,0,7920815,0,13326,11504020,MSFT
1654864215989842206,1654864215989828880,160,2,7370,T,A,263800000000,5,0,0,130,13326,11504021,MSFT
1654864215989842206,1654864215989828880,160,2,7370,F,B,263800000000,5,0,7093407,130,13326,11504021,MSFT
1654864215989842206,1654864215989828880,160,2,7370,C,B,263800000000,5,0,7093407,130,13326,11504021,MSFT
1654864215989866144,1654864215989852549,160,2,7370,A,A,264530000000,100,0,12673379,0,13595,11504022,MSFT
1654864215989866144,1654864215989853457,160,2,7370,A,A,264530000000,100,0,12673383,0,12687,11504023,MSFT
1654864215989866144,1654864215989854597,160,2,7370,A,A,264530000000,100,0,12673387,130,11547,11504024,MSFT
1654864215989877164,1654864215989866414,160,2,7370,A,A,264530000000,100,0,12673407,130,10750,11504025,MSFT
1654864215989878371,1654864215989867523,160,2,7370,A,A,264520000000,100,0,12673411,130,10848,11504026,MSFT
1654864215989881098,1654864215989870360,160,2,7370,A,A,264530000000,100,0,12673415,130,10738,11504027,MSFT
1654864215990884952,1654864215990874789,160,2,7370,C,A,264530000000,100,0,12673383,130,10163,11504045,MSFT
1654864215991020143,1654864215991009916,160,2,7370,C,A,264530000000,100,0,12673379,130,10227,11504046,MSFT
1654864215991205558,1654864215991195132,160,2,7370,C,A,264530000000,100,0,12673407,130,10426,11504047,MSFT
1654864215991748511,1654864215991737340,160,2,7370,C,A,264520000000,100,0,12673411,130,11171,11504051,MSFT
1654864215992873288,1654864215992862120,160,2,7370,A,A,264170000000,100,0,12673487,130,11168,11504059,MSFT
1654864215994679763,1654864215994669667,160,2,7370,C,A,264170000000,100,0,12673487,130,10096,11504082,MSFT
1654864216000744484,1654864216000734115,160,2,7370,C,A,264530000000,100,0,12673415,130,10369,11504119,MSFT
1654864216009878128,1654864216009867619,160,2,7370,C,A,264530000000,100,0,12673387,130,10509,11504183,MSFT
1654864216178935565,1654864216178924283,160,2,7370,A,A,296070000000,6,0,12675267,130,11282,11505607,MSFT
1654864216208451293,1654864216208440351,160,2,7370,A,A,263970000000,10,0,12675595,130,10942,11505797,MSFT
1654864217150599442,1654864217150588854,160,2,7370,A,A,264790000000,11,0,12682871,130,10588,11510694,MSFT
1654864217376974485,1654864217376963081,160,2,7370,T,N,263890000000,5,0,0,130,11404,11511732,MSFT
1654864218120875641,1654864218120864330,160,2,7370,A,B,251650000000,100,0,12688211,130,11311,11514935,MSFT
1654864218120985724,1654864218120974908,160,2,7370,C,B,252980000000,100,0,509731,130,10816,11514936,MSFT
1654864218330339409,1654864218330328568,160,2,7370,A,A,263810000000,100,0,12689407,130,10841,11516186,MSFT
1654864218331752799,1654864218331742707,160,2,7370,C,A,263810000000,100,0,12689407,130,10092,11516192,MSFT
1654864218332130298,1654864218332118609,160,2,7370,T,N,263590000000,1,0,0,130,11689,11516193,MSFT
1654864218334695674,1654864218334683145,160,2,7370,T,A,263500000000,1,0,0,130,12529,11516197,MSFT
1654864218334695674,1654864218334683145,160,2,7370,F,B,263500000000,1,0,12329543,130,12529,11516197,MSFT
1654864218334695674,1654864218334683145,160,2,7370,C,B,263500000000,1,0,12329543,130,12529,11516197,MSFT
1654864218334783978,1654864218334772053,160,2,7370,T,A,263500000000,9,0,0,130,11925,11516198,MSFT
1654864218334783978,1654864218334772053,160,2,7370,F,B,263500000000,9,0,12329543,130,11925,11516198,MSFT
1654864218334783978,1654864218334772053,160,2,7370,C,B,263500000000,9,0,12329543,130,11925,11516198,MSFT
1654864218334805652,1654864218334794859,160,2,7370,A,A,263870000000,100,0,12689531,130,10793,11516199,MSFT
1654864218335828974,1654864218335818753,160,2,7370,C,A,263870000000,100,0,12689531,130,10221,11516207,MSFT
1654864218623801983,1654864218623791448,160,2,7370,C,A,265750000000,150,0,12641863,130,10535,11517129,MSFT
1654864218625369593,1654864218625358992,160,2,7370,A,A,264000000000,150,0,12690975,130,10601,11517131,MSFT
1654864218662040553,1654864218662029974,160,2,7370,A,A,263800000000,100,0,12691155,130,10579,11517406,MSFT
1654864218663468383,1654864218663458141,160,2,7370,C,A,263800000000,100,0,12691155,130,10242,11517410,MSFT
1654864218693386726,1654864218693375257,160,2,7370,T,N,263350000000,1,0,0,130,11469,11517577,MSFT
1654864218693651601,1654864218693636785,160,2,7370,T,A,263300000000,1,0,0,130,14816,11517578,MSFT
1654864218693651601,1654864218693636785,160,2,7370,F,B,263300000000,1,0,10564551,130,14816,11517578,MSFT
1654864218693651601,1654864218693636785,160,2,7370,C,B,263300000000,1,0,10564551,130,14816,11517578,MSFT
1654864218694069758,1654864218694058292,160,2,7370,T,N,263090000000,1,0,0,130,11466,11517584,MSFT
1654864219830426938,1654864219830415775,160,2,7370,A,A,263660000000,100,0,12697643,130,11163,11523214,MSFT
1654864219831842638,1654864219831832515,160,2,7370,C,A,263660000000,100,0,12697643,130,10123,11523226,MSFT
1654864220006615966,1654864220006605014,160,2,7370,A,B,80000000000,10,0,12699223,130,10952,11524108,MSFT
1654864220006910219,1654864220006805014,160,2,7370,A,B,230000000000,10,0,12699231,130,105205,11524110,MSFT
1654864220007342383,1654864220007325942,160,2,7370,A,B,238000000000,10,0,12699251,130,16441,11524117,MSFT
1654864220007475599,1654864220007464723,160,2,7370,A,B,250000000000,10,0,12699255,130,10876,11524120,MSFT
1654864220007872909,1654864220007862302,160,2,7370,A,B,191500000000,1,0,12699271,130,10607,11524123,MSFT
1654864220014546811,1654864220014531313,160,2,7370,A,B,242500000000,41,0,12699327,130,15498,11524213,MSFT
1654864220014767765,1654864220014757258,160,2,7370,A,B,245000000000,50,0,12699335,130,10507,11524217,MSFT
1654864220015304431,1654864220015293234,160,2,7370,A,B,124800000000,10,0,12699363,130,11197,11524230,MSFT
1654864220061886347,1654864220061864185,160,2,7370,T,A,263000000000,10,0,0,0,22162,11524599,MSFT
1654864220061886347,1654864220061864185,160,2,7370,F,B,263000000000,10,0,215263,0,22162,11524599,MSFT
1654864220061886347,1654864220061864185,160,2,7370,C,B,263000000000,10,0,215263,0,22162,11524599,MSFT
1654864220061886347,1654864220061864185,160,2,7370,T,A,263000000000,1,0,0,0,22162,11524600,MSFT
1654864220061886347,1654864220061864185,160,2,7370,F,B,263000000000,1,0,333619,0,22162,11524600,MSFT
1654864220061886347,1654864220061864185,160,2,7370,C,B,263000000000,1,0,333619,0,22162,11524600,MSFT
1654864220061886347,1654864220061864185,160,2,7370,T,A,263000000000,5,0,0,0,22162,11524601,MSFT
1654864220061886347,1654864220061864185,160,2,7370,F,B,263000000000,5,0,381191,0,22162,11524601,MSFT
1654864220061886347,1654864220061864185,160,2,7370,C,B,263000000000,5,0,381191,0,22162,11524601,MSFT
1654864220061886347,1654864220061864185,160,2,7370,T,A,263000000000,1,0,0,0,22162,11524602,MSFT
1654864220061886347,1654864220061864185,160,2,7370,F,B,263000000000,1,0,3039963,0,22162,11524602,MSFT
1654864220061886347,1654864220061864185,160,2,7370,C,B,263000000000,1,0,3039963,0,22162,11524602,MSFT
1654864220061886347,1654864220061864185,160,2,7370,T,A,263000000000,1,0,0,0,22162,11524603,MSFT
1654864220061886347,1654864220061864185,160,2,7370,F,B,263000000000,1,0,4449095,0,22162,11524603,MSFT
1654864220061886347,1654864220061864185,160,2,7370,C,B,263000000000,1,0,4449095,0,22162,11524603,MSFT
1654864220061886347,1654864220061864185,160,2,7370,T,A,263000000000,1,0,0,0,22162,11524604,MSFT
1654864220061886347,1654864220061864185,160,2,7370,F,B,263000000000,1,0,5231743,0,22162,11524604,MSFT
1654864220061886347,1654864220061864185,160,2,7370,C,B,263000000000,1,0,5231743,0,22162,11524604,MSFT
1654864220061886347,1654864220061864185,160,2,7370,T,A,263000000000,2,0,0,0,22162,11524605,MSFT
1654864220061886347,1654864220061864185,160,2,7370,F,B,263000000000,2,0,5709059,0,22162,11524605,MSFT
1654864220061886347,1654864220061864185,160,2,7370,C,B,263000000000,2,0,5709059,0,22162,11524605,MSFT
1654864220061886347,1654864220061864185,160,2,7370,T,A,263000000000,7,0,0,130,22162,11524606,MSFT
1654864220061886347,1654864220061864185,160,2,7370,F,B,263000000000,7,0,8753655,130,22162,11524606,MSFT
1654864220061886347,1654864220061864185,160,2,7370,C,B,263000000000,7,0,8753655,130,22162,11524606,MSFT
1654864220062594532,1654864220062579695,160,2,7370,T,A,263000000000,3,0,0,0,14837,11524611,MSFT
1654864220062594532,1654864220062579695,160,2,7370,F,B,263000000000,3,0,8753655,0,14837,11524611,MSFT
1654864220062594532,1654864220062579695,160,2,7370,C,B,263000000000,3,0,8753655,0,14837,11524611,MSFT
1654864220062594532,1654864220062579695,160,2,7370,T,A,263000000000,1,0,0,0,14837,11524612,MSFT
1654864220062594532,1654864220062579695,160,2,7370,F,B,263000000000,1,0,10516839,0,14837,11524612,MSFT
1654864220062594532,1654864220062579695,160,2,7370,C,B,263000000000,1,0,10516839,0,14837,11524612,MSFT
1654864220062594532,1654864220062579695,160,2,7370,T,A,263000000000,5,0,0,130,14837,11524613,MSFT
1654864220062594532,1654864220062579695,160,2,7370,F,B,263000000000,5,0,11109183,130,14837,11524613,MSFT
1654864220062594532,1654864220062579695,160,2,7370,C,B,263000000000,5,0,11109183,130,14837,11524613,MSFT
1654864220062615588,1654864220062604162,160,2,7370,A,A,263770000000,100,0,12700367,130,11426,11524614,MSFT
1654864220065178021,1654864220065167387,160,2,7370,C,A,263770000000,100,0,12700367,130,10634,11524615,MSFT
1654864220160434067,1654864220160420478,160,2,7370,T,A,262990000000,1,0,0,130,13589,11525629,MSFT
1654864220160434067,1654864220160420478,160,2,7370,F,B,262990000000,1,0,9738899,130,13589,11525629,MSFT
1654864220160434067,1654864220160420478,160,2,7370,C,B,262990000000,1,0,9738899,130,13589,11525629,MSFT
1654864220162105992,1654864220162095336,160,2,7370,A,A,263600000000,100,0,12702831,130,10656,11525644,MSFT
1654864220163400411,1654864220163389810,160,2,7370,A,A,263250000000,100,0,12702887,130,10601,11525654,MSFT
1654864220163487039,1654864220163475537,160,2,7370,C,A,319890000000,100,0,12570863,0,11502,11525656,MSFT
1654864220163487039,1654864220163475537,160,2,7370,A,A,315900000000,100,0,12702895,130,11502,11525656,MSFT
1654864220163720488,1654864220163710123,160,2,7370,C,A,263600000000,100,0,12702831,130,10365,11525657,MSFT
1654864220164484731,1654864220164472280,160,2,7370,T,A,262880000000,10,0,0,130,12451,11525661,MSFT
1654864220164484731,1654864220164472280,160,2,7370,F,B,262880000000,10,0,3698263,130,12451,11525661,MSFT
1654864220164484731,1654864220164472280,160,2,7370,C,B,262880000000,10,0,3698263,130,12451,11525661,MSFT
1654864220164506338,1654864220164494697,160,2,7370,A,A,263170000000,100,0,12702907,130,11641,11525662,MSFT
1654864220165150806,1654864220165140737,160,2,7370,C,A,263250000000,100,0,12702887,130,10069,11525675,MSFT
1654864220165533594,1654864220165523075,160,2,7370,C,A,263170000000,100,0,12702907,130,10519,11525679,MSFT
1654864220165991328,1654864220165978326,160,2,7370,A,A,263250000000,100,0,12702951,130,13002,11525681,MSFT
1654864220166011095,1654864220166000192,160,2,7370,A,A,263250000000,100,0,12702959,130,10903,11525682,MSFT
1654864220167551606,1654864220167541552,160,2,7370,C,A,263250000000,100,0,12702951,130,10054,11525689,MSFT
1654864220167887449,1654864220167877415,160,2,7370,C,A,263250000000,100,0,12702959,130,10034,11525690,MSFT
1654864220174588724,1654864220174576784,160,2,7370,A,A,263160000000,100,0,12703263,130,11940,11525781,MSFT
1654864220175843656,1654864220175833356,160,2,7370,A,A,263550000000,100,0,12703351,130,10300,11525815,MSFT
1654864220175956882,1654864220175946992,160,2,7370,C,A,263160000000,100,0,12703263,130,9890,11525819,MSFT
1654864220177351541,1654864220177341076,160,2,7370,C,A,263550000000,100,0,12703351,130,10465,11525850,MSFT
1654864220179845236,1654864220179834625,160,2,7370,A,A,263080000000,100,0,12703411,130,10611,11525877,MSFT
1654864220181348331,1654864220181338308,160,2,7370,C,A,263080000000,100,0,12703411,130,10023,11525885,MSFT
1654864220351972378,1654864220351961876,160,2,7370,A,A,268800000000,12,0,12704407,130,10502,11526764,MSFT
1654864220723320715,1654864220723309289,160,2,7370,T,N,262620000000,22,0,0,130,11426,11528968,MSFT
1654864220724893651,1654864220724877567,160,2,7370,T,A,262500000000,7,0,0,0,16084,11528984,MSFT
1654864220724893651,1654864220724877567,160,2,7370,F,B,262500000000,7,0,258079,0,16084,11528984,MSFT
1654864220724893651,1654864220724877567,160,2,7370,C,B,262500000000,7,0,258079,0,16084,11528984,MSFT
1654864220724893651,1654864220724877567,160,2,7370,T,A,262470000000,3,0,0,0,16084,11528985,MSFT
1654864220724893651,1654864220724877567,160,2,7370,F,B,262470000000,3,0,215579,0,16084,11528985,MSFT
1654864220724893651,1654864220724877567,160,2,7370,C,B,262470000000,3,0,215579,0,16084,11528985,MSFT
1654864220724893651,1654864220724877567,160,2,7370,T,A,262400000000,7,0,0,0,16084,11528986,MSFT
1654864220724893651,1654864220724877567,160,2,7370,F,B,262400000000,7,0,388195,0,16084,11528986,MSFT
1654864220724893651,1654864220724877567,160,2,7370,C,B,262400000000,7,0,388195,0,16084,11528986,MSFT
1654864220724893651,1654864220724877567,160,2,7370,T,A,262400000000,1,0,0,130,16084,11528987,MSFT
1654864220724893651,1654864220724877567,160,2,7370,F,B,262400000000,1,0,828271,130,16084,11528987,MSFT
1654864220724893651,1654864220724877567,160,2,7370,C,B,262400000000,1,0,828271,130,16084,11528987,MSFT
1654864220724898025,1654864220724877567,160,2,7370,T,A,262400000000,4,0,0,0,20458,11528988,MSFT
1654864220724898025,1654864220724877567,160,2,7370,F,B,262400000000,4,0,3491719,0,20458,11528988,MSFT
1654864220724898025,1654864220724877567,160,2,7370,C,B,262400000000,4,0,3491719,0,20458,11528988,MSFT
1654864220724898025,1654864220724877567,160,2,7370,T,N,262380000000,10,0,0,0,20458,11528989,MSFT
1654864220724898025,1654864220724877567,160,2,7370,T,N,262340000000,34,0,0,0,20458,11528990,MSFT
1654864220724898025,1654864220724877567,160,2,7370,T,A,262100000000,2,0,0,0,20458,11528991,MSFT
1654864220724898025,1654864220724877567,160,2,7370,F,B,262100000000,2,0,418103,0,20458,11528991,MSFT
1654864220724898025,1654864220724877567,160,2,7370,C,B,262100000000,2,0,418103,0,20458,11528991,MSFT
1654864220724898025,1654864220724877567,160,2,7370,T,A,262000000000,1,0,0,130,20458,11528992,MSFT
1654864220724898025,1654864220724877567,160,2,7370,F,B,262000000000,1,0,381251,130,20458,11528992,MSFT
1654864220724898025,1654864220724877567,160,2,7370,C,B,262000000000,1,0,381251,130,20458,11528992,MSFT
1654864220724906139,1654864220724877567,160,2,7370,T,A,262000000000,2,0,0,0,28572,11528993,MSFT
1654864220724906139,1654864220724877567,160,2,7370,F,B,262000000000,2,0,390919,0,28572,11528993,MSFT
1654864220724906139,1654864220724877567,160,2,7370,C,B,262000000000,2,0,390919,0,28572,11528993,MSFT
1654864220724906139,1654864220724877567,160,2,7370,T,A,262000000000,10,0,0,0,28572,11528994,MSFT
1654864220724906139,1654864220724877567,160,2,7370,F,B,262000000000,10,0,410123,0,28572,11528994,MSFT
1654864220724906139,1654864220724877567,160,2,7370,C,B,262000000000,10,0,410123,0,28572,11528994,MSFT
1654864220724906139,1654864220724877567,160,2,7370,T,A,262000000000,1,0,0,0,28572,11528995,MSFT
1654864220724906139,1654864220724877567,160,2,7370,F,B,262000000000,1,0,2009431,0,28572,11528995,MSFT
1654864220724906139,1654864220724877567,160,2,7370,C,B,262000000000,1,0,2009431,0,28572,11528995,MSFT
1654864220724906139,1654864220724877567,160,2,7370,T,A,262000000000,2,0,0,0,28572,11528996,MSFT
1654864220724906139,1654864220724877567,160,2,7370,F,B,262000000000,2,0,4375827,0,28572,11528996,MSFT
1654864220724906139,1654864220724877567,160,2,7370,C,B,262000000000,2,0,4375827,0,28572,11528996,MSFT
1654864220724906139,1654864220724877567,160,2,7370,T,A,262000000000,9,0,0,0,28572,11528997,MSFT
1654864220724906139,1654864220724877567,160,2,7370,F,B,262000000000,9,0,4697707,0,28572,11528997,MSFT
1654864220724906139,1654864220724877567,160,2,7370,C,B,262000000000,9,0,4697707,0,28572,11528997,MSFT
1654864220724906139,1654864220724877567,160,2,7370,T,A,262000000000,5,0,0,0,28572,11528998,MSFT
1654864220724906139,1654864220724877567,160,2,7370,F,B,262000000000,5,0,6894235,0,28572,11528998,MSFT
1654864220724906139,1654864220724877567,160,2,7370,C,B,262000000000,5,0,6894235,0,28572,11528998,MSFT
1654864220724906139,1654864220724877567,160,2,7370,T,A,262000000000,1,0,0,0,28572,11528999,MSFT
1654864220724906139,1654864220724877567,160,2,7370,F,B,262000000000,1,0,7419159,0,28572,11528999,MSFT
1654864220724906139,1654864220724877567,160,2,7370,C,B,262000000000,1,0,7419159,0,28572,11528999,MSFT
1654864220724906139,1654864220724877567,160,2,7370,T,A,262000000000,1,0,0,130,28572,11529000,MSFT
1654864220724906139,1654864220724877567,160,2,7370,F,B,262000000000,1,0,7450819,130,28572,11529000,MSFT
1654864220724906139,1654864220724877567,160,2,7370,C,B,262000000000,1,0,7450819,130,28572,11529000,MSFT
1654864220724913902,1654864220724903366,160,2,7370,A,A,263670000000,100,0,12706775,130,10536,11529001,MSFT
1654864220724919408,1654864220724905772,160,2,7370,A,A,263650000000,100,0,12706783,130,13636,11529002,MSFT
1654864220731654070,1654864220731644126,160,2,7370,C,A,263650000000,100,0,12706783,130,9944,11529033,MSFT
1654864220744931235,1654864220744921222,160,2,7370,C,A,263670000000,100,0,12706775,130,10013,11529088,MSFT
1654864220782574489,1654864220782563038,160,2,7370,A,A,274310000000,100,0,12707283,130,11451,11529252,MSFT
1654864220782604373,1654864220782593916,160,2,7370,C,A,276140000000,100,0,12654015,130,10457,11529253,MSFT
1654864220782652959,1654864220782638265,160,2,7370,C,A,319200000000,100,0,12597291,0,14694,11529254,MSFT
1654864220782652959,1654864220782638265,160,2,7370,A,A,315000000000,100,0,12707287,130,14694,11529254,MSFT
1654864220866492986,1654864220866482521,160,2,7370,A,A,275640000000,100,0,12707627,130,10465,11529538,MSFT
1654864220866523005,1654864220866512818,160,2,7370,C,A,274310000000,100,0,12707283,130,10187,11529539,MSFT
1654864220866713657,1654864220866703453,160,2,7370,A,A,263520000000,100,0,12707647,130,10204,11529540,MSFT
1654864220868287637,1654864220868276968,160,2,7370,C,A,263520000000,100,0,12707647,130,10669,11529549,MSFT
1654864220902648769,1654864220902638185,160,2,7370,A,A,262970000000,10,0,12708027,130,10584,11529890,MSFT
1654864220937838517,1654864220937826704,160,2,7370,A,B,250330000000,100,0,12708263,130,11813,11530017,MSFT
1654864220937867537,1654864220937857358,160,2,7370,C,B,251650000000,100,0,12688211,130,10179,11530018,MSFT
1654864221259165354,1654864221259154997,160,2,7370,A,A,263490000000,100,0,12710463,130,10357,11531841,MSFT
1654864221260600432,1654864221260590387,160,2,7370,C,A,263490000000,100,0,12710463,130,10045,11531843,MSFT
1654864221453283697,1654864221453273108,160,2,7370,A,B,262300000000,1,0,12711195,130,10589,11532670,MSFT
1654864221803589418,1654864221803575570,160,2,7370,T,N,262720000000,34,0,0,0,13848,11534157,MSFT
1654864221803589418,1654864221803575570,160,2,7370,T,N,262770000000,7,0,0,0,13848,11534158,MSFT
1654864221803589418,1654864221803575570,160,2,7370,T,N,262790000000,59,0,0,130,13848,11534159,MSFT
1654864222684482887,1654864222684471503,160,2,7370,T,A,262300000000,1,0,0,130,11384,11540260,MSFT
1654864222684482887,1654864222684471503,160,2,7370,F,B,262300000000,1,0,12711195,130,11384,11540260,MSFT
1654864222684482887,1654864222684471503,160,2,7370,C,B,262300000000,1,0,12711195,130,11384,11540260,MSFT
1654864222684498660,1654864222684487657,160,2,7370,T,N,262250000000,7,0,0,130,11003,11540261,MSFT
1654864222684847667,1654864222684837659,160,2,7370,A,A,263480000000,100,0,12718103,130,10008,11540267,MSFT
1654864222684870310,1654864222684859991,160,2,7370,A,A,263470000000,100,0,12718111,130,10319,11540268,MSFT
1654864222684894077,1654864222684883754,160,2,7370,A,A,263450000000,100,0,12718155,130,10323,11540269,MSFT
1654864222686432726,1654864222686422641,160,2,7370,C,A,263480000000,100,0,12718103,130,10085,11540271,MSFT
1654864222686927326,1654864222686917500,160,2,7370,C,A,263470000000,100,0,12718111,130,9826,11540272,MSFT
1654864222687230698,1654864222687220634,160,2,7370,C,A,263450000000,100,0,12718155,130,10064,11540273,MSFT
1654864223101600781,1654864223101589703,160,2,7370,T,N,262450000000,9,0,0,130,11078,11542253,MSFT
1654864223150248408,1654864223150237102,160,2,7370,T,N,262500000000,4,0,0,130,11306,11542436,MSFT
1654864223447259172,1654864223447248107,160,2,7370,A,A,262780000000,100,0,12721907,130,11065,11543653,MSFT
1654864223448737725,1654864223448727246,160,2,7370,C,A,262780000000,100,0,12721907,130,10479,11543665,MSFT
1654864225141881845,1654864225141866361,160,2,7370,T,A,262000000000,1,0,0,0,15484,11550455,MSFT
1654864225141881845,1654864225141866361,160,2,7370,F,B,262000000000,1,0,11453219,0,15484,11550455,MSFT
1654864225141881845,1654864225141866361,160,2,7370,C,B,262000000000,1,0,11453219,0,15484,11550455,MSFT
1654864225141881845,1654864225141866361,160,2,7370,T,N,262000000000,10,0,0,130,15484,11550456,MSFT
1654864226296328611,1654864226296317943,160,2,7370,A,A,262760000000,100,0,12736143,130,10668,11556191,MSFT
1654864226297791108,1654864226297780031,160,2,7370,C,A,262760000000,100,0,12736143,130,11077,11556195,MSFT
1654864226300452612,1654864226300440735,160,2,7370,T,N,262000000000,34,0,0,130,11877,11556203,MSFT
1654864226594198249,1654864226594187949,160,2,7370,C,A,266000000000,10,0,12477295,130,10300,11557003,MSFT
1654864226883712328,1654864226883701146,160,2,7370,T,N,262000000000,5,0,0,130,11182,11558922,MSFT
1654864228411338910,1654864228411328584,160,2,7370,A,B,252080000000,5,0,12746571,130,10326,11566437,MSFT
1654864229492702201,1654864229492691740,160,2,7370,C,A,264000000000,150,0,12690975,130,10461,11570605,MSFT
1654864229494233906,1654864229494223346,160,2,7370,A,A,262000000000,150,0,12751379,130,10560,11570609,MSFT
1654864229494267091,1654864229494256621,160,2,7370,A,A,273790000000,100,0,12751399,130,10470,11570610,MSFT
1654864229494299039,1654864229494288494,160,2,7370,C,A,275640000000,100,0,12707627,130,10545,11570611,MSFT
1654864229538110151,1654864229538097718,160,2,7370,T,N,261970000000,3,0,0,0,12433,11570685,MSFT
1654864229538110151,1654864229538097718,160,2,7370,T,B,262000000000,97,0,0,130,12433,11570686,MSFT
1654864229538110151,1654864229538097718,160,2,7370,F,A,262000000000,97,0,12751379,130,12433,11570686,MSFT
1654864229538110151,1654864229538097718,160,2,7370,C,A,262000000000,97,0,12751379,130,12433,11570686,MSFT
1654864229577324457,1654864229577312852,160,2,7370,T,B,262000000000,53,0,0,130,11605,11570865,MSFT
1654864229577324457,1654864229577312852,160,2,7370,F,A,262000000000,53,0,12751379,130,11605,11570865,MSFT
1654864229577324457,1654864229577312852,160,2,7370,C,A,262000000000,53,0,12751379,130,11605,11570865,MSFT
1654864229577346339,1654864229577335106,160,2,7370,A,B,261680000000,100,0,12751763,130,11233,11570866,MSFT
1654864229577350549,1654864229577337235,160,2,7370,A,B,261600000000,100,0,12751771,130,13314,11570867,MSFT
1654864229577360577,1654864229577350554,160,2,7370,A,B,261600000000,100,0,12751787,130,10023,11570868,MSFT
1654864229578368969,1654864229578358980,160,2,7370,C,B,261600000000,100,0,12751771,130,9989,11570878,MSFT
1654864229587681248,1654864229587671293,160,2,7370,C,B,261600000000,100,0,12751787,130,9955,11570887,MSFT
1654864229597364172,1654864229597354108,160,2,7370,C,B,261680000000,100,0,12751763,130,10064,11570906,MSFT
1654864230828947216,1654864230828931950,160,2,7370,T,A,261600000000,6,0,0,0,15266,11578272,MSFT
1654864230828947216,1654864230828931950,160,2,7370,F,B,261600000000,6,0,1282327,0,15266,11578272,MSFT
1654864230828947216,1654864230828931950,160,2,7370,C,B,261600000000,6,0,1282327,0,15266,11578272,MSFT
1654864230828947216,1654864230828931950,160,2,7370,T,A,261580000000,3,0,0,0,15266,11578273,MSFT
1654864230828947216,1654864230828931950,160,2,7370,F,B,261580000000,3,0,698711,0,15266,11578273,MSFT
1654864230828947216,1654864230828931950,160,2,7370,C,B,261580000000,3,0,698711,0,15266,11578273,MSFT
1654864230828947216,1654864230828931950,160,2,7370,T,A,261500000000,1,0,0,130,15266,11578274,MSFT
1654864230828947216,1654864230828931950,160,2,7370,F,B,261500000000,1,0,7446203,130,15266,11578274,MSFT
1654864230828947216,1654864230828931950,160,2,7370,C,B,261500000000,1,0,7446203,130,15266,11578274,MSFT
1654864231200640529,1654864231200629919,160,2,7370,A,A,262540000000,10,0,12758575,130,10610,11580444,MSFT
1654864232208141110,1654864232208130864,160,2,7370,A,A,266500000000,2,0,12762479,130,10246,11586823,MSFT
1654864232596143811,1654864232596132298,160,2,7370,T,N,261750000000,34,0,0,130,11513,11588803,MSFT
1654864232596170060,1654864232596158911,160,2,7370,T,N,261750000000,3,0,0,130,11149,11588804,MSFT
1654864232596267715,1654864232596256579,160,2,7370,T,N,261750000000,100,0,0,130,11136,11588805,MSFT
1654864232596304617,1654864232596293128,160,2,7370,T,N,261750000000,100,0,0,130,11489,11588807,MSFT
1654864234528849333,1654864234528834157,160,2,7370,A,B,237000000000,5,0,12774735,130,15176,11601723,MSFT
1654864236323232226,1654864236323221907,160,2,7370,C,A,266500000000,2,0,12762479,130,10319,11613016,MSFT
1654864236325091697,1654864236325081465,160,2,7370,A,A,266500000000,2,0,12784995,130,10232,11613021,MSFT
1654864238712769068,1654864238712758756,160,2,7370,C,A,262540000000,10,0,12758575,130,10312,11625099,MSFT
1654864238837173156,1654864238837162765,160,2,7370,A,A,262250000000,100,0,12808539,130,10391,11625715,MSFT
1654864238837197855,1654864238837185641,160,2,7370,A,A,262250000000,100,0,12808547,128,12214,11625716,MSFT
1654864238838634379,1654864238838624500,160,2,7370,C,A,262250000000,100,0,12808539,130,9879,11625722,MSFT
1654864238838924646,1654864238838914826,160,2,7370,C,A,262250000000,100,0,12808547,130,9820,11625724,MSFT
1654864239746895119,1654864239746883775,160,2,7370,T,N,261550000000,18,0,0,130,11344,11629681,MSFT
1654864240365127138,1654864240365115733,160,2,7370,A,A,263490000000,100,0,12814591,130,11405,11631855,MSFT
1654864240365151852,1654864240365141479,160,2,7370,A,A,263480000000,100,0,12814599,130,10373,11631858,MSFT
1654864240370526686,1654864240370516309,160,2,7370,C,A,263490000000,100,0,12814591,130,10377,11632091,MSFT
1654864240370748944,1654864240370737634,160,2,7370,C,A,263480000000,100,0,12814599,130,11310,11632096,MSFT
1654864240432773023,1654864240432758286,160,2,7370,T,N,261550000000,82,0,0,0,14737,11632529,MSFT
1654864240432773023,1654864240432758286,160,2,7370,T,N,261510000000,200,0,0,0,14737,11632530,MSFT
1654864240432773023,1654864240432758286,160,2,7370,T,N,261490000000,100,0,0,0,14737,11632531,MSFT
1654864240432773023,1654864240432758286,160,2,7370,T,N,261490000000,93,0,0,130,14737,11632532,MSFT
1654864241682273343,1654864241682261901,160,2,7370,T,N,261490000000,2,0,0,130,11442,11638684,MSFT
1654864242769119828,1654864242769108343,160,2,7370,T,N,261490000000,3,0,0,130,11485,11643065,MSFT
1654864242769155070,1654864242769143874,160,2,7370,T,N,261490000000,2,0,0,130,11196,11643066,MSFT
1654864243519158147,1654864243519147867,160,2,7370,A,A,261700000000,35,0,12826487,130,10280,11645773,MSFT
1654864243519636720,1654864243519626168,160,2,7370,A,A,261700000000,65,0,12826607,130,10552,11645775,MSFT
1654864243624324381,1654864243624313386,160,2,7370,A,B,260940000000,200,0,12827475,130,10995,11646268,MSFT
1654864243624339431,1654864243624328451,160,2,7370,A,A,262310000000,200,0,12827479,130,10980,11646269,MSFT
1654864243748282238,1654864243748271378,160,2,7370,A,B,260000000000,10,0,12827995,130,10860,11646800,MSFT
1654864243784887731,1654864243784876724,160,2,7370,C,B,260940000000,200,0,12827475,0,11007,11646947,MSFT
1654864243784887731,1654864243784876724,160,2,7370,A,B,261000000000,200,0,12828119,130,11007,11646947,MSFT
1654864243784901201,1654864243784890698,160,2,7370,C,A,262310000000,200,0,12827479,0,10503,11646948,MSFT
1654864243784901201,1654864243784890698,160,2,7370,A,A,262000000000,200,0,12828123,130,10503,11646948,MSFT
1654864243833938077,1654864243833924835,160,2,7370,T,A,261330000000,2,0,0,0,13242,11647565,MSFT
1654864243833938077,1654864243833924835,160,2,7370,F,B,261330000000,2,0,8296875,0,13242,11647565,MSFT
1654864243833938077,1654864243833924835,160,2,7370,C,B,261330000000,2,0,8296875,0,13242,11647565,MSFT
1654864243833938077,1654864243833924835,160,2,7370,T,A,261200000000,1,0,0,130,13242,11647566,MSFT
1654864243833938077,1654864243833924835,160,2,7370,F,B,261200000000,1,0,2246307,130,13242,11647566,MSFT
1654864243833938077,1654864243833924835,160,2,7370,C,B,261200000000,1,0,2246307,130,13242,11647566,MSFT
1654864243833960570,1654864243833950202,160,2,7370,A,A,261620000000,100,0,12828575,130,10368,11647567,MSFT
1654864243834859572,1654864243834848618,160,2,7370,A,A,263450000000,100,0,12828643,130,10954,11647568,MSFT
1654864243834873095,1654864243834862806,160,2,7370,C,B,261000000000,200,0,12828119,130,10289,11647569,MSFT
1654864243834882505,1654864243834872125,160,2,7370,A,A,263440000000,100,0,12828655,130,10380,11647570,MSFT
1654864243834903202,1654864243834892746,160,2,7370,A,A,263430000000,100,0,12828671,130,10456,11647571,MSFT
1654864243834925509,1654864243834914793,160,2,7370,A,A,263430000000,100,0,12828679,130,10716,11647572,MSFT
1654864243834978304,1654864243834968413,160,2,7370,C,A,261620000000,100,0,12828575,130,9891,11647573,MSFT
1654864243836281962,1654864243836271213,160,2,7370,C,A,263450000000,100,0,12828643,130,10749,11647579,MSFT
1654864243836545020,1654864243836534976,160,2,7370,C,A,263440000000,100,0,12828655,130,10044,11647583,MSFT
1654864243836858876,1654864243836848741,160,2,7370,C,A,263430000000,100,0,12828671,130,10135,11647584,MSFT
1654864243837044402,1654864243837034265,160,2,7370,C,A,263430000000,100,0,12828679,130,10137,11647585,MSFT
1654864243889492705,1654864243889482295,160,2,7370,A,B,260970000000,200,0,12828935,130,10410,11647749,MSFT
1654864243901529982,1654864243901519263,160,2,7370,C,B,260970000000,200,0,12828935,130,10719,11647778,MSFT
1654864243901542618,1654864243901532173,160,2,7370,A,B,260890000000,200,0,12828967,130,10445,11647779,MSFT
1654864243912170529,1654864243912160362,160,2,7370,C,B,260890000000,200,0,12828967,130,10167,11647829,MSFT
1654864243912183947,1654864243912173332,160,2,7370,A,B,260810000000,200,0,12828987,130,10615,11647830,MSFT
1654864244012590773,1654864244012579672,160,2,7370,C,A,262000000000,200,0,12828123,0,11101,11648067,MSFT
1654864244012590773,1654864244012579672,160,2,7370,A,A,261990000000,200,0,12829351,130,11101,11648067,MSFT
1654864244025596342,1654864244025585958,160,2,7370,C,A,261990000000,200,0,12829351,0,10384,11648115,MSFT
1654864244025596342,1654864244025585958,160,2,7370,A,A,261830000000,200,0,12829411,130,10384,11648115,MSFT
1654864244277761802,1654864244277751198,160,2,7370,C,A,261830000000,200,0,12829411,0,10604,11649085,MSFT
1654864244277761802,1654864244277751198,160,2,7370,A,A,261810000000,200,0,12830179,130,10604,11649085,MSFT
1654864244394588604,1654864244394578050,160,2,7370,C,A,261810000000,200,0,12830179,130,10554,11649677,MSFT
1654864244394602708,1654864244394591876,160,2,7370,A,A,261920000000,200,0,12830515,130,10832,11649678,MSFT
1654864244490759506,1654864244490749017,160,2,7370,C,B,260810000000,200,0,12828987,0,10489,11650496,MSFT
1654864244490759506,1654864244490749017,160,2,7370,A,B,260850000000,200,0,12831003,130,10489,11650496,MSFT
1654864244500264458,1654864244500253900,160,2,7370,C,A,261920000000,200,0,12830515,0,10558,11650536,MSFT
1654864244500264458,1654864244500253900,160,2,7370,A,A,261910000000,200,0,12831043,130,10558,11650536,MSFT
1654864244594325214,1654864244594314852,160,2,7370,C,A,261910000000,200,0,12831043,0,10362,11651412,MSFT
1654864244594325214,1654864244594314852,160,2,7370,A,A,261900000000,200,0,12831475,130,10362,11651412,MSFT
1654864244675403214,1654864244675393271,160,2,7370,C,B,260850000000,200,0,12831003,130,9943,11652120,MSFT
1654864244675417713,1654864244675406262,160,2,7370,A,B,260770000000,200,0,12832047,128,11451,11652121,MSFT
1654864244700810566,1654864244700799894,160,2,7370,A,A,261750000000,100,0,12832299,130,10672,11652484,MSFT
1654864244700832650,1654864244700821601,160,2,7370,A,A,261740000000,100,0,12832307,130,11049,11652485,MSFT
1654864244700855210,1654864244700844885,160,2,7370,A,A,261730000000,100,0,12832331,130,10325,11652486,MSFT
1654864244700879774,1654864244700869384,160,2,7370,A,A,261710000000,100,0,12832347,130,10390,11652487,MSFT
1654864244702509902,1654864244702499839,160,2,7370,C,A,261750000000,100,0,12832299,130,10063,11652492,MSFT
1654864244702743560,1654864244702733564,160,2,7370,C,A,261740000000,100,0,12832307,130,9996,11652497,MSFT
1654864244703460521,1654864244703450470,160,2,7370,C,A,261730000000,100,0,12832331,130,10051,11652503,MSFT
1654864244704026833,1654864244704016828,160,2,7370,C,A,261710000000,100,0,12832347,130,10005,11652505,MSFT
1654864245049946889,1654864245049936523,160,2,7370,C,A,261900000000,200,0,12831475,0,10366,11654354,MSFT
1654864245049946889,1654864245049936523,160,2,7370,A,A,261830000000,200,0,12833639,130,10366,11654354,MSFT
1654864245241298101,1654864245241287558,160,2,7370,C,A,261830000000,200,0,12833639,0,10543,11655372,MSFT
1654864245241298101,1654864245241287558,160,2,7370,A,A,261820000000,200,0,12834339,130,10543,11655372,MSFT
1654864245245660491,1654864245245650247,160,2,7370,C,A,261820000000,200,0,12834339,130,10244,11655374,MSFT
1654864245245674215,1654864245245663770,160,2,7370,A,A,261890000000,200,0,12834355,130,10445,11655375,MSFT
1654864245346040979,1654864245346030546,160,2,7370,C,A,261890000000,200,0,12834355,0,10433,11655658,MSFT
1654864245346040979,1654864245346030546,160,2,7370,A,A,261880000000,200,0,12834611,130,10433,11655658,MSFT
1654864245346090875,1654864245346080418,160,2,7370,C,A,261880000000,200,0,12834611,0,10457,11655660,MSFT
1654864245346090875,1654864245346080418,160,2,7370,A,A,261810000000,200,0,12834615,130,10457,11655660,MSFT
1654864245413821771,1654864245413811471,160,2,7370,C,A,261810000000,200,0,12834615,130,10300,11655930,MSFT
1654864245413835272,1654864245413824757,160,2,7370,A,A,261890000000,200,0,12834831,130,10515,11655931,MSFT
1654864245535292029,1654864245535281347,160,2,7370,C,A,261890000000,200,0,12834831,0,10682,11657001,MSFT
1654864245535292029,1654864245535281347,160,2,7370,A,A,261860000000,200,0,12835367,130,10682,11657001,MSFT
1654864245739047765,1654864245739037620,160,2,7370,A,A,262020000000,100,0,12836531,130,10145,11658857,MSFT
1654864245739066146,1654864245739055832,160,2,7370,C,B,260770000000,200,0,12832047,130,10314,11658858,MSFT
1654864245740491531,1654864245740481535,160,2,7370,C,A,262020000000,100,0,12836531,130,9996,11658879,MSFT
1654864245789947599,1654864245789937097,160,2,7370,A,B,260710000000,200,0,12836903,130,10502,11659085,MSFT
1654864245805372357,1654864245805361979,160,2,7370,C,B,260710000000,200,0,12836903,0,10378,11659146,MSFT
1654864245805372357,1654864245805361979,160,2,7370,A,B,260720000000,200,0,12836943,130,10378,11659146,MSFT
1654864245828892193,1654864245828881221,160,2,7370,C,B,260720000000,200,0,12836943,0,10972,11659305,MSFT
1654864245828892193,1654864245828881221,160,2,7370,A,B,260740000000,200,0,12837035,130,10972,11659305,MSFT
1654864246055472150,1654864246055461681,160,2,7370,C,A,261860000000,200,0,12835367,130,10469,11660660,MSFT
1654864246055484279,1654864246055473756,160,2,7370,A,A,261930000000,200,0,12838471,130,10523,11660661,MSFT
1654864246160102397,1654864246160092098,160,2,7370,C,B,260740000000,200,0,12837035,0,10299,11661327,MSFT
1654864246160102397,1654864246160092098,160,2,7370,A,B,260750000000,200,0,12838835,130,10299,11661327,MSFT
1654864246370233982,1654864246370223565,160,2,7370,C,A,261930000000,200,0,12838471,0,10417,11662173,MSFT
1654864246370233982,1654864246370223565,160,2,7370,A,A,261810000000,200,0,12839495,130,10417,11662173,MSFT
1654864246492165639,1654864246492155566,160,2,7370,C,A,261810000000,200,0,12839495,130,10073,11662875,MSFT
1654864246492179743,1654864246492169489,160,2,7370,A,A,261890000000,200,0,12839943,130,10254,11662877,MSFT
1654864246596389777,1654864246596379510,160,2,7370,C,B,260750000000,200,0,12838835,0,10267,11663198,MSFT
1654864246596389777,1654864246596379510,160,2,7370,A,B,260770000000,200,0,12840351,130,10267,11663198,MSFT
1654864246596402935,1654864246596392579,160,2,7370,C,A,261890000000,200,0,12839943,0,10356,11663199,MSFT
1654864246596402935,1654864246596392579,160,2,7370,A,A,261860000000,200,0,12840355,130,10356,11663199,MSFT
1654864246610566914,1654864246610556700,160,2,7370,C,A,261860000000,200,0,12840355,130,10214,11663246,MSFT
1654864246610579200,1654864246610568903,160,2,7370,A,A,261950000000,200,0,12840423,130,10297,11663247,MSFT
1654864246713611915,1654864246713601514,160,2,7370,C,B,260770000000,200,0,12840351,0,10401,11663875,MSFT
1654864246713611915,1654864246713601514,160,2,7370,A,B,260780000000,200,0,12840935,130,10401,11663875,MSFT
1654864246740632154,1654864246740621894,160,2,7370,C,B,260780000000,200,0,12840935,0,10260,11664131,MSFT
1654864246740632154,1654864246740621894,160,2,7370,A,B,260880000000,200,0,12841051,130,10260,11664131,MSFT
1654864247347295589,1654864247347284959,160,2,7370,C,B,260880000000,200,0,12841051,0,10630,11667564,MSFT
1654864247347295589,1654864247347284959,160,2,7370,A,B,260890000000,200,0,12843299,130,10630,11667564,MSFT
1654864247533616162,1654864247533605644,160,2,7370,C,B,260890000000,200,0,12843299,0,10518,11668327,MSFT
1654864247533616162,1654864247533605644,160,2,7370,A,B,260900000000,200,0,12844031,130,10518,11668327,MSFT
1654864247666720293,1654864247666709437,160,2,7370,A,A,261780000000,100,0,12844659,130,10856,11669059,MSFT
1654864247666739314,1654864247666729071,160,2,7370,C,B,260900000000,200,0,12844031,130,10243,11669060,MSFT
1654864247668009877,1654864247667999423,160,2,7370,C,A,261780000000,100,0,12844659,130,10454,11669067,MSFT
1654864247718777470,1654864247718766548,160,2,7370,A,B,260700000000,200,0,12845151,130,10922,11669299,MSFT
1654864247741720944,1654864247741710528,160,2,7370,C,B,260700000000,200,0,12845151,0,10416,11669359,MSFT
1654864247741720944,1654864247741710528,160,2,7370,A,B,260790000000,200,0,12845223,130,10416,11669359,MSFT
1654864247848906621,1654864247848896098,160,2,7370,C,A,261950000000,200,0,12840423,0,10523,11669584,MSFT
1654864247848906621,1654864247848896098,160,2,7370,A,A,261880000000,200,0,12845379,130,10523,11669584,MSFT
1654864248056040674,1654864248056029819,160,2,7370,C,B,260790000000,200,0,12845223,0,10855,11670107,MSFT
1654864248056040674,1654864248056029819,160,2,7370,A,B,260850000000,200,0,12845975,130,10855,11670107,MSFT
1654864248401665620,1654864248401655161,160,2,7370,C,B,260850000000,200,0,12845975,0,10459,11671644,MSFT
1654864248401665620,1654864248401655161,160,2,7370,A,B,260860000000,200,0,12846811,130,10459,11671644,MSFT
1654864248438687510,1654864248438676966,160,2,7370,C,B,260860000000,200,0,12846811,0,10544,11671841,MSFT
1654864248438687510,1654864248438676966,160,2,7370,A,B,260870000000,200,0,12846879,130,10544,11671841,MSFT
1654864248544635713,1654864248544625406,160,2,7370,C,A,261880000000,200,0,12845379,130,10307,11673313,MSFT
1654864248544648289,1654864248544637943,160,2,7370,A,A,261950000000,200,0,12847363,130,10346,11673314,MSFT
1654864248629904642,1654864248629893917,160,2,7370,C,B,260870000000,200,0,12846879,0,10725,11674146,MSFT
1654864248629904642,1654864248629893917,160,2,7370,A,B,260890000000,200,0,12847947,130,10725,11674146,MSFT
1654864248913707345,1654864248913696927,160,2,7370,C,B,260890000000,200,0,12847947,130,10418,11677037,MSFT
1654864248913720346,1654864248913709858,160,2,7370,A,B,260790000000,200,0,12849355,130,10488,11677038,MSFT
1654864248962229020,1654864248962218300,160,2,7370,C,A,261950000000,200,0,12847363,0,10720,11677215,MSFT
1654864248962229020,1654864248962218300,160,2,7370,A,A,261940000000,200,0,12849543,130,10720,11677215,MSFT
1654864249016263723,1654864249016252939,160,2,7370,C,B,260790000000,200,0,12849355,0,10784,11677523,MSFT
1654864249016263723,1654864249016252939,160,2,7370,A,B,260800000000,200,0,12849707,130,10784,11677523,MSFT
1654864249068298049,1654864249068287519,160,2,7370,C,A,261940000000,200,0,12849543,0,10530,11678021,MSFT
1654864249068298049,1654864249068287519,160,2,7370,A,A,261930000000,200,0,12849911,130,10530,11678021,MSFT
1654864249106588706,1654864249106578425,160,2,7370,C,A,261930000000,200,0,12849911,0,10281,11678602,MSFT
1654864249106588706,1654864249106578425,160,2,7370,A,A,261920000000,200,0,12850183,130,10281,11678602,MSFT
1654864249227488256,1654864249227475350,160,2,7370,T,N,261010000000,5,0,0,130,12906,11679249,MSFT
1654864249242996349,1654864249242984957,160,2,7370,T,N,261010000000,5,0,0,130,11392,11679480,MSFT
1654864249427530854,1654864249427519880,160,2,7370,C,B,260800000000,200,0,12849707,0,10974,11680461,MSFT
1654864249427530854,1654864249427519880,160,2,7370,A,B,260870000000,200,0,12851835,130,10974,11680461,MSFT
1654864249718000181,1654864249717989158,160,2,7370,C,B,260870000000,200,0,12851835,0,11023,11682843,MSFT
1654864249718000181,1654864249717989158,160,2,7370,A,B,260880000000,200,0,12852983,130,11023,11682843,MSFT
1654864250029789656,1654864250029779313,160,2,7370,C,A,261920000000,200,0,12850183,130,10343,11684678,MSFT
1654864250029803588,1654864250029792355,160,2,7370,A,A,261990000000,200,0,12854211,130,11233,11684679,MSFT
1654864250407663874,1654864250407653224,160,2,7370,C,A,261990000000,200,0,12854211,0,10650,11686321,MSFT
1654864250407663874,1654864250407653224,160,2,7370,A,A,261970000000,200,0,12855279,130,10650,11686321,MSFT
1654864250583784855,1654864250583774059,160,2,7370,C,A,261970000000,200,0,12855279,0,10796,11686685,MSFT
1654864250583784855,1654864250583774059,160,2,7370,A,A,261960000000,200,0,12855547,130,10796,11686685,MSFT
1654864250919575728,1654864250919558309,160,2,7370,T,N,261500000000,34,0,0,0,17419,11687734,MSFT
1654864250919575728,1654864250919558309,160,2,7370,T,N,261500000000,100,0,0,0,17419,11687735,MSFT
1654864250919575728,1654864250919558309,160,2,7370,T,N,261560000000,100,0,0,0,17419,11687736,MSFT
1654864250919575728,1654864250919558309,160,2,7370,T,N,261600000000,139,0,0,0,17419,11687737,MSFT
1654864250919575728,1654864250919558309,160,2,7370,T,N,261600000000,461,0,0,0,17419,11687738,MSFT
1654864250919575728,1654864250919558309,160,2,7370,T,B,261700000000,35,0,0,0,17419,11687739,MSFT
1654864250919575728,1654864250919558309,160,2,7370,F,A,261700000000,35,0,12826487,0,17419,11687739,MSFT
1654864250919575728,1654864250919558309,160,2,7370,C,A,261700000000,35,0,12826487,0,17419,11687739,MSFT
1654864250919575728,1654864250919558309,160,2,7370,T,B,261700000000,65,0,0,130,17419,11687740,MSFT
1654864250919575728,1654864250919558309,160,2,7370,F,A,261700000000,65,0,12826607,130,17419,11687740,MSFT
1654864250919575728,1654864250919558309,160,2,7370,C,A,261700000000,65,0,12826607,130,17419,11687740,MSFT
1654864250919596232,1654864250919585810,160,2,7370,A,B,261140000000,100,0,12856219,130,10422,11687741,MSFT
1654864250919602356,1654864250919588582,160,2,7370,A,B,261140000000,100,0,12856227,130,13774,11687743,MSFT
1654864250919613517,1654864250919602066,160,2,7370,A,B,261140000000,100,0,12856247,128,11451,11687744,MSFT
1654864250919668264,1654864250919657970,160,2,7370,A,B,261160000000,100,0,12856271,130,10294,11687747,MSFT
1654864250920621380,1654864250920611414,160,2,7370,C,B,261140000000,100,0,12856227,130,9966,11687751,MSFT
1654864250924947865,1654864250924937877,160,2,7370,C,B,261160000000,100,0,12856271,130,9988,11687773,MSFT
1654864250930010385,1654864250929999954,160,2,7370,C,B,261140000000,100,0,12856247,130,10431,11687795,MSFT
1654864250939613744,1654864250939603250,160,2,7370,C,B,261140000000,100,0,12856219,130,10494,11687874,MSFT
1654864250987600475,1654864250987590260,160,2,7370,C,A,261960000000,200,0,12855547,130,10215,11688012,MSFT
1654864250987612441,1654864250987602248,160,2,7370,A,A,262040000000,200,0,12856527,130,10193,11688013,MSFT
1654864251094310596,1654864251094300054,160,2,7370,C,B,260880000000,200,0,12852983,0,10542,11689454,MSFT
1654864251094310596,1654864251094300054,160,2,7370,A,B,260970000000,200,0,12857151,130,10542,11689454,MSFT
1654864251157647699,1654864251157637764,160,2,7370,C,B,260970000000,200,0,12857151,130,9935,11690530,MSFT
1654864251157660804,1654864251157650323,160,2,7370,A,B,260850000000,200,0,12857743,130,10481,11690531,MSFT
1654864251162970028,1654864251162959887,160,2,7370,C,A,262040000000,200,0,12856527,130,10141,11690633,MSFT
1654864251162982530,1654864251162972029,160,2,7370,A,A,262140000000,200,0,12857795,130,10501,11690634,MSFT
1654864251269617266,1654864251269605996,160,2,7370,C,B,260850000000,200,0,12857743,0,11270,11691431,MSFT
1654864251269617266,1654864251269605996,160,2,7370,A,B,260920000000,200,0,12858347,130,11270,11691431,MSFT
1654864251303637422,1654864251303626788,160,2,7370,C,A,262140000000,200,0,12857795,0,10634,11691712,MSFT
1654864251303637422,1654864251303626788,160,2,7370,A,A,262060000000,200,0,12858475,130,10634,11691712,MSFT
1654864251441725827,1654864251441715308,160,2,7370,C,A,262060000000,200,0,12858475,0,10519,11692263,MSFT
1654864251441725827,1654864251441715308,160,2,7370,A,A,262050000000,200,0,12858835,130,10519,11692263,MSFT
1654864251892572738,1654864251892561642,160,2,7370,T,N,261720000000,20,0,0,130,11096,11693663,MSFT
1654864251919081613,1654864251919070951,160,2,7370,C,A,262050000000,200,0,12858835,0,10662,11693748,MSFT
1654864251919081613,1654864251919070951,160,2,7370,A,A,262030000000,200,0,12860355,130,10662,11693748,MSFT
1654864251968131631,1654864251968120964,160,2,7370,C,B,260920000000,200,0,12858347,0,10667,11693965,MSFT
1654864251968131631,1654864251968120964,160,2,7370,A,B,260930000000,200,0,12860571,130,10667,11693965,MSFT
1654864252125259675,1654864252125248776,160,2,7370,C,B,257970000000,2,0,367927,130,10899,11694382,MSFT
1654864252126783959,1654864252126773603,160,2,7370,A,B,259970000000,2,0,12861035,130,10356,11694386,MSFT
1654864252153240673,1654864252153229936,160,2,7370,C,A,262030000000,200,0,12860355,0,10737,11694445,MSFT
1654864252153240673,1654864252153229936,160,2,7370,A,A,262020000000,200,0,12861115,130,10737,11694445,MSFT
1654864252282329834,1654864252282319324,160,2,7370,C,A,262020000000,200,0,12861115,0,10510,11694909,MSFT
1654864252282329834,1654864252282319324,160,2,7370,A,A,262010000000,200,0,12861635,130,10510,11694909,MSFT
1654864252375074915,1654864252375064747,160,2,7370,C,B,260930000000,200,0,12860571,130,10168,11695486,MSFT
1654864252375088796,1654864252375078184,160,2,7370,A,B,260810000000,200,0,12861955,130,10612,11695487,MSFT
1654864252506553150,1654864252506542737,160,2,7370,C,A,262010000000,200,0,12861635,0,10413,11696394,MSFT
1654864252506553150,1654864252506542737,160,2,7370,A,A,262000000000,200,0,12862627,130,10413,11696394,MSFT
1654864252544574260,1654864252544563863,160,2,7370,C,A,262000000000,200,0,12862627,0,10397,11696535,MSFT
1654864252544574260,1654864252544563863,160,2,7370,A,A,261930000000,200,0,12862691,130,10397,11696535,MSFT
1654864252891806453,1654864252891796129,160,2,7370,C,B,260810000000,200,0,12861955,0,10324,11698940,MSFT
1654864252891806453,1654864252891796129,160,2,7370,A,B,260910000000,200,0,12864211,130,10324,11698940,MSFT
1654864252938568003,1654864252938557813,160,2,7370,C,A,261930000000,200,0,12862691,130,10190,11699180,MSFT
1654864252938580282,1654864252938569844,160,2,7370,A,A,262010000000,200,0,12864387,130,10438,11699181,MSFT
1654864253040905043,1654864253040894361,160,2,7370,C,B,260910000000,200,0,12864211,0,10682,11699485,MSFT
1654864253040905043,1654864253040894361,160,2,7370,A,B,260920000000,200,0,12864695,130,10682,11699485,MSFT
1654864253173151656,1654864253173141351,160,2,7370,C,A,262010000000,200,0,12864387,130,10305,11700188,MSFT
1654864253173163779,1654864253173153076,160,2,7370,A,A,262080000000,200,0,12865423,130,10703,11700189,MSFT
1654864253204460658,1654864253204450168,160,2,7370,C,A,262080000000,200,0,12865423,130,10490,11700547,MSFT
1654864253204473510,1654864253204462844,160,2,7370,A,A,262160000000,200,0,12865699,130,10666,11700548,MSFT
1654864253212878644,1654864253212868504,160,2,7370,C,B,260920000000,200,0,12864695,130,10140,11700589,MSFT
1654864253212892428,1654864253212882021,160,2,7370,A,B,260850000000,200,0,12865811,130,10407,11700590,MSFT
1654864253310073018,1654864253310061961,160,2,7370,C,A,262160000000,200,0,12865699,0,11057,11701064,MSFT
1654864253310073018,1654864253310061961,160,2,7370,A,A,262150000000,200,0,12866123,130,11057,11701064,MSFT
1654864253323079980,1654864253323069464,160,2,7370,C,B,260850000000,200,0,12865811,0,10516,11701130,MSFT
1654864253323079980,1654864253323069464,160,2,7370,A,B,260860000000,200,0,12866239,130,10516,11701130,MSFT
1654864253323095150,1654864253323084748,160,2,7370,C,A,262150000000,200,0,12866123,0,10402,11701131,MSFT
1654864253323095150,1654864253323084748,160,2,7370,A,A,262120000000,200,0,12866243,130,10402,11701131,MSFT
1654864253374801836,1654864253374791326,160,2,7370,C,B,260860000000,200,0,12866239,0,10510,11701286,MSFT
1654864253374801836,1654864253374791326,160,2,7370,A,B,260930000000,200,0,12866439,130,10510,11701286,MSFT
1654864253375383645,1654864253375373381,160,2,7370,C,A,262120000000,200,0,12866243,130,10264,11701289,MSFT
1654864253375395879,1654864253375385394,160,2,7370,A,A,262230000000,200,0,12866447,130,10485,11701290,MSFT
1654864253375522755,1654864253375512761,160,2,7370,C,B,260930000000,200,0,12866439,130,9994,11701291,MSFT
1654864253375536069,1654864253375525275,160,2,7370,A,B,260840000000,200,0,12866479,130,10794,11701292,MSFT
1654864253375601179,1654864253375591097,160,2,7370,C,A,262230000000,200,0,12866447,130,10082,11701293,MSFT
1654864253375613979,1654864253375603375,160,2,7370,A,A,262300000000,200,0,12866483,130,10604,11701294,MSFT
1654864253480202794,1654864253480192190,160,2,7370,C,A,262300000000,200,0,12866483,0,10604,11701749,MSFT
1654864253480202794,1654864253480192190,160,2,7370,A,A,262290000000,200,0,12866823,130,10604,11701749,MSFT
1654864253558249138,1654864253558238771,160,2,7370,C,B,260840000000,200,0,12866479,0,10367,11702287,MSFT
1654864253558249138,1654864253558238771,160,2,7370,A,B,260900000000,200,0,12867591,130,10367,11702287,MSFT
1654864253582388572,1654864253582378091,160,2,7370,C,A,262290000000,200,0,12866823,0,10481,11702391,MSFT
1654864253582388572,1654864253582378091,160,2,7370,A,A,262280000000,200,0,12867759,130,10481,11702391,MSFT
1654864253690870605,1654864253690860664,160,2,7370,C,B,260900000000,200,0,12867591,130,9941,11702906,MSFT
1654864253690883859,1654864253690873601,160,2,7370,A,B,260820000000,200,0,12868279,130,10258,11702907,MSFT
1654864253701341576,1654864253701331102,160,2,7370,C,A,262280000000,200,0,12867759,0,10474,11703002,MSFT
1654864253701341576,1654864253701331102,160,2,7370,A,A,262220000000,200,0,12868499,130,10474,11703002,MSFT
1654864253791718445,1654864253791707981,160,2,7370,C,B,260820000000,200,0,12868279,0,10464,11703324,MSFT
1654864253791718445,1654864253791707981,160,2,7370,A,B,260830000000,200,0,12868939,130,10464,11703324,MSFT
1654864253791733302,1654864253791722868,160,2,7370,C,A,262220000000,200,0,12868499,0,10434,11703325,MSFT
1654864253791733302,1654864253791722868,160,2,7370,A,A,262210000000,200,0,12868943,130,10434,11703325,MSFT
1654864253892977453,1654864253892966245,160,2,7370,C,A,262210000000,200,0,12868943,0,11208,11703716,MSFT
1654864253892977453,1654864253892966245,160,2,7370,A,A,262200000000,200,0,12869239,130,11208,11703716,MSFT
1654864253998897917,1654864253998887702,160,2,7370,C,A,262200000000,200,0,12869239,0,10215,11704481,MSFT
1654864253998897917,1654864253998887702,160,2,7370,A,A,261910000000,200,0,12869671,130,10215,11704481,MSFT
1654864254067961260,1654864254067951102,160,2,7370,C,B,260830000000,200,0,12868939,130,10158,11704837,MSFT
1654864254067983359,1654864254067972745,160,2,7370,A,B,260760000000,200,0,12869939,130,10614,11704839,MSFT
1654864254171408511,1654864254171398229,160,2,7370,C,A,261910000000,200,0,12869671,0,10282,11705241,MSFT
1654864254171408511,1654864254171398229,160,2,7370,A,A,261900000000,200,0,12870199,130,10282,11705241,MSFT
1654864254255028590,1654864254255018460,160,2,7370,C,B,260760000000,200,0,12869939,130,10130,11706942,MSFT
1654864254255043484,1654864254255032229,160,2,7370,A,B,260690000000,200,0,12870875,130,11255,11706943,MSFT
1654864254273367367,1654864254273356843,160,2,7370,C,A,261900000000,200,0,12870199,0,10524,11707525,MSFT
1654864254273367367,1654864254273356843,160,2,7370,A,A,261890000000,200,0,12871171,130,10524,11707525,MSFT
1654864254565006524,1654864254564995908,160,2,7370,C,B,260690000000,200,0,12870875,0,10616,11710514,MSFT
1654864254565006524,1654864254564995908,160,2,7370,A,B,260720000000,200,0,12873311,130,10616,11710514,MSFT
1654864254575010165,1654864254574999723,160,2,7370,C,A,261890000000,200,0,12871171,0,10442,11710540,MSFT
1654864254575010165,1654864254574999723,160,2,7370,A,A,261820000000,200,0,12873339,130,10442,11710540,MSFT
1654864254789415143,1654864254789404430,160,2,7370,C,A,261820000000,200,0,12873339,0,10713,11711873,MSFT
1654864254789415143,1654864254789404430,160,2,7370,A,A,261810000000,200,0,12874575,130,10713,11711873,MSFT
1654864254804474733,1654864254804464211,160,2,7370,C,A,261810000000,200,0,12874575,130,10522,11711927,MSFT
1654864254804488144,1654864254804477433,160,2,7370,A,A,261900000000,200,0,12874639,130,10711,11711928,MSFT
1654864254804693154,1654864254804682854,160,2,7370,C,A,261900000000,200,0,12874639,130,10300,11711929,MSFT
1654864254804705455,1654864254804694361,160,2,7370,A,A,261970000000,200,0,12874675,130,11094,11711930,MSFT
1654864254805537469,1654864254805527226,160,2,7370,C,A,261970000000,200,0,12874675,130,10243,11711932,MSFT
1654864254805551320,1654864254805540626,160,2,7370,A,A,262040000000,200,0,12874719,130,10694,11711933,MSFT
1654864254874825902,1654864254874815703,160,2,7370,C,A,262040000000,200,0,12874719,130,10199,11712346,MSFT
1654864254874838963,1654864254874828637,160,2,7370,A,A,262120000000,200,0,12875107,130,10326,11712348,MSFT
1654864254940302334,1654864254940291945,160,2,7370,C,B,260720000000,200,0,12873311,0,10389,11712590,MSFT
1654864254940302334,1654864254940291945,160,2,7370,A,B,260780000000,200,0,12875431,130,10389,11712590,MSFT
1654864255078410558,1654864255078400291,160,2,7370,C,A,262120000000,200,0,12875107,0,10267,11713454,MSFT
1654864255078410558,1654864255078400291,160,2,7370,A,A,262110000000,200,0,12875907,130,10267,11713454,MSFT
1654864255080822035,1654864255080811584,160,2,7370,C,A,262110000000,200,0,12875907,0,10451,11713462,MSFT
1654864255080822035,1654864255080811584,160,2,7370,A,A,261960000000,200,0,12875923,130,10451,11713462,MSFT
1654864255083953864,1654864255083943800,160,2,7370,C,A,261960000000,200,0,12875923,130,10064,11713472,MSFT
1654864255083967946,1654864255083957657,160,2,7370,A,A,262060000000,200,0,12875951,130,10289,11713473,MSFT
1654864255153918147,1654864255153907608,160,2,7370,C,A,262060000000,200,0,12875951,130,10539,11713991,MSFT
1654864255153931275,1654864255153920991,160,2,7370,A,A,262240000000,200,0,12876471,130,10284,11713992,MSFT
1654864255465378396,1654864255465367728,160,2,7370,C,A,262240000000,200,0,12876471,0,10668,11715422,MSFT
1654864255465378396,1654864255465367728,160,2,7370,A,A,262100000000,200,0,12878363,130,10668,11715422,MSFT
1654864255648504845,1654864255648493843,160,2,7370,C,A,262100000000,200,0,12878363,0,11002,11716170,MSFT
1654864255648504845,1654864255648493843,160,2,7370,A,A,262060000000,200,0,12879091,130,11002,11716170,MSFT
1654864256277220293,1654864256277210129,160,2,7370,C,A,262060000000,200,0,12879091,130,10164,11718854,MSFT
1654864256277234710,1654864256277223555,160,2,7370,A,A,262140000000,200,0,12882087,130,11155,11718855,MSFT
1654864256303062438,1654864256303051481,160,2,7370,C,A,266500000000,2,0,12784995,130,10957,11718935,MSFT
1654864256377567730,1654864256377557479,160,2,7370,C,A,262140000000,200,0,12882087,0,10251,11719098,MSFT
1654864256377567730,1654864256377557479,160,2,7370,A,A,262130000000,200,0,12882391,130,10251,11719098,MSFT
1654864256474110864,1654864256474100164,160,2,7370,C,B,260780000000,200,0,12875431,0,10700,11719524,MSFT
1654864256474110864,1654864256474100164,160,2,7370,A,B,260790000000,200,0,12882675,130,10700,11719524,MSFT
1654864256484069712,1654864256484059164,160,2,7370,C,B,260790000000,200,0,12882675,0,10548,11719533,MSFT
1654864256484069712,1654864256484059164,160,2,7370,A,B,260850000000,200,0,12882687,130,10548,11719533,MSFT
1654864256484084412,1654864256484073728,160,2,7370,C,A,262130000000,200,0,12882391,0,10684,11719534,MSFT
1654864256484084412,1654864256484073728,160,2,7370,A,A,262120000000,200,0,12882691,130,10684,11719534,MSFT
1654864256557115495,1654864256557105049,160,2,7370,C,A,262120000000,200,0,12882691,0,10446,11719751,MSFT
1654864256557115495,1654864256557105049,160,2,7370,A,A,261920000000,200,0,12882835,130,10446,11719751,MSFT
1654864256799009718,1654864256798999491,160,2,7370,C,A,261920000000,200,0,12882835,130,10227,11721189,MSFT
1654864256799023792,1654864256799013298,160,2,7370,A,A,262030000000,200,0,12883919,130,10494,11721190,MSFT
1654864256868749529,1654864256868739262,160,2,7370,C,A,262030000000,200,0,12883919,130,10267,11721447,MSFT
1654864256868762537,1654864256868752236,160,2,7370,A,A,262100000000,200,0,12884167,130,10301,11721448,MSFT
1654864256927804969,1654864256927794727,160,2,7370,C,A,262100000000,200,0,12884167,130,10242,11721682,MSFT
1654864256927818335,1654864256927807644,160,2,7370,A,A,262190000000,200,0,12884375,130,10691,11721683,MSFT
1654864256971527472,1654864256971515730,160,2,7370,T,N,261060000000,5,0,0,130,11742,11721981,MSFT
1654864257032814726,1654864257032804221,160,2,7370,C,B,260850000000,200,0,12882687,0,10505,11722156,MSFT
1654864257032814726,1654864257032804221,160,2,7370,A,B,260990000000,200,0,12885143,130,10505,11722156,MSFT
1654864257075104929,1654864257075093791,160,2,7370,C,B,260990000000,200,0,12885143,128,11138,11722262,MSFT
1654864257075117819,1654864257075107383,160,2,7370,A,B,260910000000,200,0,12885231,130,10436,11722265,MSFT
1654864257083268232,1654864257083258200,160,2,7370,C,B,260910000000,200,0,12885231,130,10032,11722277,MSFT
1654864257083282269,1654864257083271939,160,2,7370,A,B,260840000000,200,0,12885255,130,10330,11722278,MSFT
1654864257083296865,1654864257083286566,160,2,7370,C,A,262190000000,200,0,12884375,0,10299,11722279,MSFT
1654864257083296865,1654864257083286566,160,2,7370,A,A,262110000000,200,0,12885263,130,10299,11722279,MSFT
1654864257194967046,1654864257194956350,160,2,7370,C,A,262110000000,200,0,12885263,0,10696,11722848,MSFT
1654864257194967046,1654864257194956350,160,2,7370,A,A,261900000000,200,0,12885695,130,10696,11722848,MSFT
1654864257211766056,1654864257211756008,160,2,7370,C,A,261900000000,200,0,12885695,130,10048,11722902,MSFT
1654864257211780957,1654864257211768501,160,2,7370,A,A,262000000000,200,0,12885819,130,12456,11722903,MSFT
1654864257384952977,1654864257384942564,160,2,7370,C,B,260840000000,200,0,12885255,130,10413,11724243,MSFT
1654864257384966395,1654864257384956067,160,2,7370,A,B,260750000000,200,0,12886823,130,10328,11724244,MSFT
1654864257501315511,1654864257501304536,160,2,7370,C,A,262000000000,200,0,12885819,0,10975,11725069,MSFT
1654864257501315511,1654864257501304536,160,2,7370,A,A,261870000000,200,0,12887531,130,10975,11725069,MSFT
1654864257586111053,1654864257586101002,160,2,7370,C,A,261870000000,200,0,12887531,130,10051,11725411,MSFT
1654864257586124166,1654864257586113892,160,2,7370,A,A,262010000000,200,0,12887951,130,10274,11725412,MSFT
1654864257586399696,1654864257586389727,160,2,7370,C,A,262010000000,200,0,12887951,130,9969,11725413,MSFT
1654864257586412854,1654864257586402333,160,2,7370,A,A,262080000000,200,0,12887995,130,10521,11725414,MSFT
1654864257709473997,1654864257709462628,160,2,7370,C,B,260750000000,200,0,12886823,0,11369,11725844,MSFT
1654864257709473997,1654864257709462628,160,2,7370,A,B,260760000000,200,0,12888799,130,11369,11725844,MSFT
1654864257757538892,1654864257757528563,160,2,7370,C,B,260760000000,200,0,12888799,0,10329,11726108,MSFT
1654864257757538892,1654864257757528563,160,2,7370,A,B,260880000000,200,0,12888907,130,10329,11726108,MSFT
1654864257765354827,1654864257765344854,160,2,7370,C,B,260880000000,200,0,12888907,130,9973,11726137,MSFT
1654864257765368700,1654864257765357850,160,2,7370,A,B,260800000000,200,0,12888971,130,10850,11726138,MSFT
1654864257958678968,1654864257958668582,160,2,7370,C,A,262080000000,200,0,12887995,0,10386,11726984,MSFT
1654864257958678968,1654864257958668582,160,2,7370,A,A,261880000000,200,0,12889623,130,10386,11726984,MSFT
1654864258135812714,1654864258135802329,160,2,7370,C,A,261880000000,200,0,12889623,0,10385,11728696,MSFT
1654864258135812714,1654864258135802329,160,2,7370,A,A,261870000000,200,0,12891195,130,10385,11728696,MSFT
1654864258208858922,1654864258208848358,160,2,7370,C,A,261870000000,200,0,12891195,0,10564,11728968,MSFT
1654864258208858922,1654864258208848358,160,2,7370,A,A,261830000000,200,0,12891627,130,10564,11728968,MSFT
1654864258407986439,1654864258407975884,160,2,7370,C,A,261830000000,200,0,12891627,0,10555,11730117,MSFT
1654864258407986439,1654864258407975884,160,2,7370,A,A,261820000000,200,0,12892623,130,10555,11730117,MSFT
1654864258422988764,1654864258422978649,160,2,7370,C,A,261820000000,200,0,12892623,130,10115,11730249,MSFT
1654864258423002541,1654864258422992124,160,2,7370,A,A,261890000000,200,0,12892783,130,10417,11730250,MSFT
1654864259258990116,1654864259258979451,160,2,7370,C,A,261890000000,200,0,12892783,0,10665,11733925,MSFT
1654864259258990116,1654864259258979451,160,2,7370,A,A,261880000000,200,0,12896067,130,10665,11733925,MSFT
1654864259272995278,1654864259272984934,160,2,7370,C,B,260800000000,200,0,12888971,0,10344,11733975,MSFT
1654864259272995278,1654864259272984934,160,2,7370,A,B,260830000000,200,0,12896155,130,10344,11733975,MSFT
1654864259398021563,1654864259398010874,160,2,7370,C,B,260830000000,200,0,12896155,130,10689,11734766,MSFT
1654864259398033849,1654864259398023473,160,2,7370,A,B,260760000000,200,0,12896715,130,10376,11734767,MSFT
1654864259490506246,1654864259490493925,160,2,7370,A,A,261840000000,100,0,12897007,130,12321,11735177,MSFT
1654864259491936646,1654864259491926586,160,2,7370,C,A,261840000000,100,0,12897007,130,10060,11735185,MSFT
1654864259557279318,1654864259557269009,160,2,7370,C,B,260760000000,200,0,12896715,0,10309,11735621,MSFT
1654864259557279318,1654864259557269009,160,2,7370,A,B,260770000000,200,0,12897367,130,10309,11735621,MSFT
1654864259623324669,1654864259623314105,160,2,7370,C,B,260770000000,200,0,12897367,0,10564,11735939,MSFT
1654864259623324669,1654864259623314105,160,2,7370,A,B,260890000000,200,0,12897547,130,10564,11735939,MSFT
1654864259684159323,1654864259684148995,160,2,7370,A,A,261800000000,100,0,12897871,130,10328,11736215,MSFT
1654864259685550026,1654864259685540227,160,2,7370,C,A,261800000000,100,0,12897871,130,9799,11736224,MSFT
1654864259717519186,1654864259717508321,160,2,7370,C,A,264790000000,11,0,12682871,130,10865,11736317,MSFT
1654864259739007480,1654864259738997268,160,2,7370,C,A,261880000000,200,0,12896067,130,10212,11736370,MSFT
1654864259739021360,1654864259739010910,160,2,7370,A,A,261960000000,200,0,12898231,130,10450,11736371,MSFT
1654864259755218662,1654864259755207757,160,2,7370,C,B,260890000000,200,0,12897547,130,10905,11736417,MSFT
1654864259755230687,1654864259755220370,160,2,7370,A,B,260820000000,200,0,12898295,130,10317,11736418,MSFT
1654864259834834694,1654864259834824574,160,2,7370,C,A,261960000000,200,0,12898231,130,10120,11736657,MSFT
1654864259834849089,1654864259834838459,160,2,7370,A,A,262040000000,200,0,12898475,130,10630,11736658,MSFT
1654864259940906904,1654864259940896353,160,2,7370,C,A,262040000000,200,0,12898475,0,10551,11737337,MSFT
1654864259940906904,1654864259940896353,160,2,7370,A,A,262030000000,200,0,12898831,130,10551,11737337,MSFT
1654864260044135123,1654864260044124750,160,2,7370,C,A,262030000000,200,0,12898831,0,10373,11737919,MSFT
1654864260044135123,1654864260044124750,160,2,7370,A,A,262020000000,200,0,12899283,130,10373,11737919,MSFT
1654864260058208703,1654864260058198242,160,2,7370,C,A,262020000000,200,0,12899283,0,10461,11738066,MSFT
1654864260058208703,1654864260058198242,160,2,7370,A,A,261910000000,200,0,12899359,130,10461,11738066,MSFT
1654864260377143740,1654864260377133019,160,2,7370,A,A,261120000000,6,0,12900391,130,10721,11740051,MSFT
1654864260377371490,1654864260377360320,160,2,7370,T,B,261120000000,6,0,0,130,11170,11740054,MSFT
1654864260377371490,1654864260377360320,160,2,7370,F,A,261120000000,6,0,12900391,130,11170,11740054,MSFT
1654864260377371490,1654864260377360320,160,2,7370,C,A,261120000000,6,0,12900391,130,11170,11740054,MSFT
1654864260377393484,1654864260377382059,160,2,7370,A,B,261030000000,100,0,12900431,130,11425,11740055,MSFT
1654864260390099175,1654864260390089110,160,2,7370,C,B,261030000000,100,0,12900431,130,10065,11740080,MSFT
1654864260447198249,1654864260447187864,160,2,7370,C,B,260820000000,200,0,12898295,130,10385,11741017,MSFT
1654864260447211623,1654864260447200931,160,2,7370,A,B,260710000000,200,0,12900847,130,10692,11741018,MSFT
1654864260548032410,1654864260548021801,160,2,7370,C,B,260710000000,200,0,12900847,0,10609,11741688,MSFT
1654864260548032410,1654864260548021801,160,2,7370,A,B,260720000000,200,0,12901331,130,10609,11741688,MSFT
1654864260548809930,1654864260548792251,160,2,7370,C,B,260720000000,200,0,12901331,0,17679,11741691,MSFT
1654864260548809930,1654864260548792251,160,2,7370,A,B,260750000000,200,0,12901335,130,17679,11741691,MSFT
1654864260650469794,1654864260650459254,160,2,7370,C,B,260750000000,200,0,12901335,0,10540,11742174,MSFT
1654864260650469794,1654864260650459254,160,2,7370,A,B,260760000000,200,0,12901663,130,10540,11742174,MSFT
1654864260660474866,1654864260660464394,160,2,7370,C,A,261910000000,200,0,12899359,0,10472,11742208,MSFT
1654864260660474866,1654864260660464394,160,2,7370,A,A,261830000000,200,0,12901695,130,10472,11742208,MSFT
1654864260845530375,1654864260845520113,160,2,7370,C,A,261830000000,200,0,12901695,130,10262,11743152,MSFT
1654864260845543839,1654864260845533210,160,2,7370,A,A,261920000000,200,0,12902267,130,10629,11743153,MSFT
1654864260854959711,1654864260854948239,160,2,7370,C,B,260760000000,200,0,12901663,0,11472,11743188,MSFT
1654864260854959711,1654864260854948239,160,2,7370,A,B,260770000000,200,0,12902347,130,11472,11743188,MSFT
1654864260855838134,1654864260855828257,160,2,7370,C,A,261920000000,200,0,12902267,130,9877,11743210,MSFT
1654864260855851247,1654864260855840798,160,2,7370,A,A,262000000000,200,0,12902363,130,10449,11743211,MSFT
1654864260960679478,1654864260960668992,160,2,7370,C,B,260770000000,200,0,12902347,0,10486,11743738,MSFT
1654864260960679478,1654864260960668992,160,2,7370,A,B,260830000000,200,0,12902743,130,10486,11743738,MSFT
1654864261220349282,1654864261220338786,160,2,7370,C,A,262000000000,200,0,12902363,0,10496,11745216,MSFT
1654864261220349282,1654864261220338786,160,2,7370,A,A,261860000000,200,0,12903595,130,10496,11745216,MSFT
1654864261530072957,1654864261530062420,160,2,7370,C,A,261860000000,200,0,12903595,0,10537,11747431,MSFT
1654864261530072957,1654864261530062420,160,2,7370,A,A,261840000000,200,0,12905183,130,10537,11747431,MSFT
1654864262005768850,1654864262005736209,160,2,7370,C,A,261840000000,200,0,12905183,0,32641,11750107,MSFT
1654864262005768850,1654864262005736209,160,2,7370,A,A,261830000000,200,0,12907843,128,32641,11750107,MSFT
1654864262189646802,1654864262189636481,160,2,7370,C,B,260830000000,200,0,12902743,130,10321,11750907,MSFT
1654864262189660876,1654864262189650079,160,2,7370,A,B,260730000000,200,0,12908971,130,10797,11750908,MSFT
1654864262229655452,1654864262229645280,160,2,7370,C,B,260730000000,200,0,12908971,130,10172,11751257,MSFT
1654864262287265740,1654864262287255024,160,2,7370,A,B,260700000000,200,0,12909839,130,10716,11751617,MSFT
1654864262372324250,1654864262372313408,160,2,7370,C,A,261830000000,200,0,12907843,0,10842,11752000,MSFT
1654864262372324250,1654864262372313408,160,2,7370,A,A,261720000000,200,0,12910115,130,10842,11752000,MSFT
1654864262461273878,1654864262461263584,160,2,7370,A,B,261020000000,200,0,12910355,130,10294,11752612,MSFT
1654864262709110885,1654864262709100525,160,2,7370,C,B,260700000000,200,0,12909839,130,10360,11753874,MSFT
1654864262760584518,1654864262760574025,160,2,7370,A,B,260690000000,200,0,12911483,130,10493,11754016,MSFT
1654864262965859793,1654864262965849312,160,2,7370,C,B,260690000000,200,0,12911483,0,10481,11755239,MSFT
1654864262965859793,1654864262965849312,160,2,7370,A,B,260710000000,200,0,12912807,130,10481,11755239,MSFT
1654864262972654379,1654864262972644360,160,2,7370,C,A,261720000000,200,0,12910115,130,10019,11755266,MSFT
1654864262972667850,1654864262972657397,160,2,7370,A,A,261790000000,200,0,12912831,130,10453,11755267,MSFT
1654864263043068677,1654864263043058546,160,2,7370,C,A,261790000000,200,0,12912831,130,10131,11755738,MSFT
1654864263043082594,1654864263043072035,160,2,7370,A,A,261880000000,200,0,12913003,130,10559,11755739,MSFT
1654864263060540176,1654864263060529808,160,2,7370,C,B,260710000000,200,0,12912807,0,10368,11755878,MSFT
1654864263060540176,1654864263060529808,160,2,7370,A,B,260720000000,200,0,12913103,130,10368,11755878,MSFT
1654864263142707072,1654864263142697031,160,2,7370,C,A,261880000000,200,0,12913003,130,10041,11756337,MSFT
1654864263142721354,1654864263142710683,160,2,7370,A,A,262020000000,200,0,12913463,130,10671,11756338,MSFT
1654864263156124636,1654864263156114016,160,2,7370,C,B,260720000000,200,0,12913103,0,10620,11756438,MSFT
1654864263156124636,1654864263156114016,160,2,7370,A,B,260780000000,200,0,12913519,130,10620,11756438,MSFT
1654864263214615322,1654864263214605258,160,2,7370,C,A,262020000000,200,0,12913463,130,10064,11756665,MSFT
1654864263214629814,1654864263214618733,160,2,7370,A,A,262130000000,200,0,12913707,130,11081,11756666,MSFT
1654864263320302158,1654864263320291518,160,2,7370,C,A,262130000000,200,0,12913707,0,10640,11757195,MSFT
1654864263320302158,1654864263320291518,160,2,7370,A,A,262120000000,200,0,12914143,130,10640,11757195,MSFT
1654864263387345358,1654864263387335055,160,2,7370,C,B,260780000000,200,0,12913519,0,10303,11757430,MSFT
1654864263387345358,1654864263387335055,160,2,7370,A,B,260850000000,200,0,12914299,130,10303,11757430,MSFT
1654864263387359492,1654864263387348975,160,2,7370,C,A,262120000000,200,0,12914143,0,10517,11757431,MSFT
1654864263387359492,1654864263387348975,160,2,7370,A,A,261960000000,200,0,12914303,130,10517,11757431,MSFT
1654864263488284870,1654864263488274683,160,2,7370,C,A,261960000000,200,0,12914303,130,10187,11757740,MSFT
1654864263488298065,1654864263488287613,160,2,7370,A,A,262030000000,200,0,12914627,130,10452,11757741,MSFT
1654864263560913525,1654864263560902741,160,2,7370,C,B,260850000000,200,0,12914299,130,10784,11758206,MSFT
1654864263560926333,1654864263560916120,160,2,7370,A,B,260770000000,200,0,12915095,130,10213,11758207,MSFT
1654864263671539664,1654864263671528731,160,2,7370,C,B,260770000000,200,0,12915095,0,10933,11758943,MSFT
1654864263671539664,1654864263671528731,160,2,7370,A,B,260830000000,200,0,12915527,130,10933,11758943,MSFT
1654864263671553641,1654864263671543193,160,2,7370,C,A,262030000000,200,0,12914627,0,10448,11758944,MSFT
1654864263671553641,1654864263671543193,160,2,7370,A,A,261840000000,200,0,12915531,130,10448,11758944,MSFT
1654864264581361897,1654864264581351266,160,2,7370,C,A,261840000000,200,0,12915531,0,10631,11764300,MSFT
1654864264581361897,1654864264581351266,160,2,7370,A,A,261830000000,200,0,12919083,130,10631,11764300,MSFT
1654864264716896839,1654864264716886527,160,2,7370,C,B,260830000000,200,0,12915527,130,10312,11764737,MSFT
1654864264716911122,1654864264716900150,160,2,7370,A,B,260720000000,200,0,12919795,130,10972,11764738,MSFT
1654864264817539088,1654864264817528411,160,2,7370,C,A,261830000000,200,0,12919083,0,10677,11765030,MSFT
1654864264817539088,1654864264817528411,160,2,7370,A,A,261820000000,200,0,12920015,130,10677,11765030,MSFT
1654864264827540792,1654864264827530465,160,2,7370,C,A,261820000000,200,0,12920015,0,10327,11765180,MSFT
1654864264827540792,1654864264827530465,160,2,7370,A,A,261780000000,200,0,12920099,130,10327,11765180,MSFT
1654864264873008519,1654864264872998459,160,2,7370,C,A,261780000000,200,0,12920099,130,10060,11765523,MSFT
1654864264873021706,1654864264873011011,160,2,7370,A,A,261870000000,200,0,12920215,130,10695,11765525,MSFT
1654864264896967351,1654864264896956754,160,2,7370,C,B,260720000000,200,0,12919795,0,10597,11766301,MSFT
1654864264896967351,1654864264896956754,160,2,7370,A,B,260730000000,200,0,12920471,130,10597,11766301,MSFT
1654864264943412899,1654864264943402199,160,2,7370,C,A,261870000000,200,0,12920215,130,10700,11766616,MSFT
1654864264943424873,1654864264943414394,160,2,7370,A,A,261970000000,200,0,12920711,130,10479,11766617,MSFT
1654864264943747818,1654864264943737684,160,2,7370,C,A,261970000000,200,0,12920711,130,10134,11766621,MSFT
1654864264943760924,1654864264943750136,160,2,7370,A,A,262050000000,200,0,12920735,130,10788,11766622,MSFT
1654864265000942677,1654864265000932269,160,2,7370,C,B,260730000000,200,0,12920471,0,10408,11767218,MSFT
1654864265000942677,1654864265000932269,160,2,7370,A,B,260740000000,200,0,12921047,130,10408,11767218,MSFT
1654864265047825045,1654864265047814374,160,2,7370,C,A,262050000000,200,0,12920735,0,10671,11767516,MSFT
1654864265047825045,1654864265047814374,160,2,7370,A,A,262040000000,200,0,12921235,130,10671,11767516,MSFT
1654864265079087167,1654864265079076659,160,2,7370,C,A,262040000000,200,0,12921235,0,10508,11768171,MSFT
1654864265079087167,1654864265079076659,160,2,7370,A,A,261990000000,200,0,12921671,130,10508,11768171,MSFT
1654864265103102959,1654864265103092637,160,2,7370,C,B,260740000000,200,0,12921047,0,10322,11768359,MSFT
1654864265103102959,1654864265103092637,160,2,7370,A,B,260750000000,200,0,12921879,130,10322,11768359,MSFT
1654864265113957591,1654864265113947495,160,2,7370,C,A,261990000000,200,0,12921671,130,10096,11768413,MSFT
1654864265113969661,1654864265113959209,160,2,7370,A,A,262120000000,200,0,12921963,130,10452,11768414,MSFT
1654864265114113919,1654864265114103949,160,2,7370,C,A,262120000000,200,0,12921963,130,9970,11768415,MSFT
1654864265114126890,1654864265114116384,160,2,7370,A,A,262220000000,200,0,12921995,130,10506,11768416,MSFT
1654864265175670877,1654864265175659583,160,2,7370,T,A,261020000000,5,0,0,130,11294,11768814,MSFT
1654864265175670877,1654864265175659583,160,2,7370,F,B,261020000000,5,0,12910355,130,11294,11768814,MSFT
1654864265175670877,1654864265175659583,160,2,7370,C,B,261020000000,5,0,12910355,130,11294,11768814,MSFT
1654864265211193881,1654864265211183454,160,2,7370,C,B,260750000000,200,0,12921879,0,10427,11768940,MSFT
1654864265211193881,1654864265211183454,160,2,7370,A,B,260760000000,200,0,12922339,130,10427,11768940,MSFT
1654864265221105545,1654864265221094960,160,2,7370,C,A,262220000000,200,0,12921995,0,10585,11768963,MSFT
1654864265221105545,1654864265221094960,160,2,7370,A,A,262210000000,200,0,12922367,130,10585,11768963,MSFT
1654864265425338678,1654864265425327471,160,2,7370,C,A,262210000000,200,0,12922367,0,11207,11769716,MSFT
1654864265425338678,1654864265425327471,160,2,7370,A,A,262200000000,200,0,12922959,130,11207,11769716,MSFT
1654864265428315587,1654864265428305096,160,2,7370,C,B,260760000000,200,0,12922339,0,10491,11769729,MSFT
1654864265428315587,1654864265428305096,160,2,7370,A,B,260800000000,200,0,12922995,130,10491,11769729,MSFT
1654864265428378030,1654864265428367169,160,2,7370,C,A,262200000000,200,0,12922959,0,10861,11769730,MSFT
1654864265428378030,1654864265428367169,160,2,7370,A,A,261960000000,200,0,12922999,130,10861,11769730,MSFT
1654864265616472706,1654864265616462328,160,2,7370,C,A,261960000000,200,0,12922999,0,10378,11770127,MSFT
1654864265616472706,1654864265616462328,160,2,7370,A,A,261930000000,200,0,12923479,130,10378,11770127,MSFT
1654864265653302647,1654864265653291533,160,2,7370,C,B,260800000000,200,0,12922995,0,11114,11770201,MSFT
1654864265653302647,1654864265653291533,160,2,7370,A,B,260850000000,200,0,12923563,130,11114,11770201,MSFT
1654864265654307298,1654864265654297286,160,2,7370,C,B,260850000000,200,0,12923563,130,10012,11770203,MSFT
1654864265654320798,1654864265654310475,160,2,7370,A,B,260770000000,200,0,12923571,130,10323,11770204,MSFT
1654864265778577677,1654864265778566421,160,2,7370,C,B,260770000000,200,0,12923571,0,11256,11770497,MSFT
1654864265778577677,1654864265778566421,160,2,7370,A,B,260820000000,200,0,12923939,130,11256,11770497,MSFT
1654864265778591290,1654864265778580947,160,2,7370,C,A,261930000000,200,0,12923479,0,10343,11770498,MSFT
1654864265778591290,1654864265778580947,160,2,7370,A,A,261880000000,200,0,12923943,130,10343,11770498,MSFT
1654864266008735060,1654864266008723580,160,2,7370,C,A,261880000000,200,0,12923943,0,11480,11771580,MSFT
1654864266008735060,1654864266008723580,160,2,7370,A,A,261870000000,200,0,12924707,130,11480,11771580,MSFT
1654864266038358628,1654864266038346939,160,2,7370,T,A,261020000000,50,0,0,130,11689,11771766,MSFT
1654864266038358628,1654864266038346939,160,2,7370,F,B,261020000000,50,0,12910355,130,11689,11771766,MSFT
1654864266038358628,1654864266038346939,160,2,7370,C,B,261020000000,50,0,12910355,130,11689,11771766,MSFT
1654864266320933863,1654864266320923526,160,2,7370,C,B,260820000000,200,0,12923939,0,10337,11773092,MSFT
1654864266320933863,1654864266320923526,160,2,7370,A,B,260850000000,200,0,12925863,130,10337,11773092,MSFT
1654864266503337457,1654864266503326982,160,2,7370,C,B,260850000000,200,0,12925863,0,10475,11773858,MSFT
1654864266503337457,1654864266503326982,160,2,7370,A,B,260860000000,200,0,12926535,130,10475,11773858,MSFT
1654864266648670531,1654864266648660278,160,2,7370,C,B,260860000000,200,0,12926535,130,10253,11774538,MSFT
1654864266648684710,1654864266648674286,160,2,7370,A,B,260790000000,200,0,12926887,130,10424,11774539,MSFT
1654864266763523019,1654864266763512305,160,2,7370,C,A,261870000000,200,0,12924707,0,10714,11775058,MSFT
1654864266763523019,1654864266763512305,160,2,7370,A,A,261770000000,200,0,12927143,130,10714,11775058,MSFT
1654864267051913961,1654864267051903463,160,2,7370,C,B,260790000000,200,0,12926887,0,10498,11776133,MSFT
1654864267051913961,1654864267051903463,160,2,7370,A,B,260800000000,200,0,12927883,130,10498,11776133,MSFT
1654864267174660407,1654864267174646791,160,2,7370,T,N,261620000000,34,0,0,0,13616,11776449,MSFT
1654864267174660407,1654864267174646791,160,2,7370,T,N,261670000000,50,0,0,0,13616,11776450,MSFT
1654864267174660407,1654864267174646791,160,2,7370,T,N,261700000000,16,0,0,130,13616,11776451,MSFT
1654864267251666173,1654864267251654602,160,2,7370,T,A,261020000000,100,0,0,130,11571,11776659,MSFT
1654864267251666173,1654864267251654602,160,2,7370,F,B,261020000000,100,0,12910355,130,11571,11776659,MSFT
1654864267251666173,1654864267251654602,160,2,7370,C,B,261020000000,100,0,12910355,130,11571,11776659,MSFT
1654864267487523078,1654864267487512802,160,2,7370,C,B,260800000000,200,0,12927883,130,10276,11777581,MSFT
1654864267487536795,1654864267487525927,160,2,7370,A,B,260710000000,200,0,12929431,130,10868,11777582,MSFT
1654864267587586604,1654864267587575867,160,2,7370,C,A,261770000000,200,0,12927143,0,10737,11778153,MSFT
1654864267587586604,1654864267587575867,160,2,7370,A,A,261760000000,200,0,12929819,130,10737,11778153,MSFT
1654864267853808403,1654864267853797738,160,2,7370,C,B,260710000000,200,0,12929431,0,10665,11779585,MSFT
1654864267853808403,1654864267853797738,160,2,7370,A,B,260740000000,200,0,12930919,130,10665,11779585,MSFT
1654864267979182839,1654864267979172652,160,2,7370,C,A,261760000000,200,0,12929819,130,10187,11780282,MSFT
1654864267979195788,1654864267979185221,160,2,7370,A,A,261830000000,200,0,12931415,130,10567,11780283,MSFT
1654864268081112973,1654864268081102386,160,2,7370,C,A,261830000000,200,0,12931415,0,10587,11780662,MSFT
1654864268081112973,1654864268081102386,160,2,7370,A,A,261820000000,200,0,12931651,130,10587,11780662,MSFT
1654864268192271143,1654864268192260892,160,2,7370,C,A,261820000000,200,0,12931651,0,10251,11780953,MSFT
1654864268192271143,1654864268192260892,160,2,7370,A,A,261730000000,200,0,12931895,130,10251,11780953,MSFT
1654864268884237363,1654864268884227318,160,2,7370,C,A,261730000000,200,0,12931895,130,10045,11784245,MSFT
1654864268884250938,1654864268884240530,160,2,7370,A,A,261800000000,200,0,12934559,130,10408,11784246,MSFT
1654864268884591311,1654864268884581201,160,2,7370,C,A,261800000000,200,0,12934559,130,10110,11784249,MSFT
1654864268884604528,1654864268884593859,160,2,7370,A,A,261870000000,200,0,12934587,130,10669,11784250,MSFT
1654864268898046925,1654864268898036509,160,2,7370,C,B,260740000000,200,0,12930919,0,10416,11784296,MSFT
1654864268898046925,1654864268898036509,160,2,7370,A,B,260750000000,200,0,12934643,130,10416,11784296,MSFT
1654864269066192284,1654864269066181780,160,2,7370,C,A,261870000000,200,0,12934587,0,10504,11784970,MSFT
1654864269066192284,1654864269066181780,160,2,7370,A,A,261860000000,200,0,12934983,130,10504,11784970,MSFT
1654864269346404775,1654864269346394405,160,2,7370,C,B,260750000000,200,0,12934643,0,10370,11786361,MSFT
1654864269346404775,1654864269346394405,160,2,7370,A,B,260790000000,200,0,12936399,130,10370,11786361,MSFT
1654864269372052729,1654864269372036574,160,2,7370,T,A,261020000000,45,0,0,0,16155,11786526,MSFT
1654864269372052729,1654864269372036574,160,2,7370,F,B,261020000000,45,0,12910355,0,16155,11786526,MSFT
1654864269372052729,1654864269372036574,160,2,7370,C,B,261020000000,45,0,12910355,0,16155,11786526,MSFT
1654864269372052729,1654864269372036574,160,2,7370,T,A,261000000000,5,0,0,0,16155,11786527,MSFT
1654864269372052729,1654864269372036574,160,2,7370,F,B,261000000000,5,0,337111,0,16155,11786527,MSFT
1654864269372052729,1654864269372036574,160,2,7370,C,B,261000000000,5,0,337111,0,16155,11786527,MSFT
1654864269372052729,1654864269372036574,160,2,7370,T,A,261000000000,2,0,0,0,16155,11786528,MSFT
1654864269372052729,1654864269372036574,160,2,7370,F,B,261000000000,2,0,434655,0,16155,11786528,MSFT
1654864269372052729,1654864269372036574,160,2,7370,C,B,261000000000,2,0,434655,0,16155,11786528,MSFT
1654864269372052729,1654864269372036574,160,2,7370,T,A,261000000000,4,0,0,130,16155,11786529,MSFT
